Workbook
Name AgeConcurrents: 'Tournament Setup'!$A$29:$A$33
Name Concurrent: 'Tournament Setup'!$A$46:$A$51
Name ShooterID: 'Tournament List'!$A$3:$A$151
Name SkeetTimes: 'Tournament Setup'!$A$98:$A$107
Name SportingTimes: 'Tournament Setup'!$C$98:$C$107
Name SquadConcurrents: 'Tournament Setup'!$A$56:$A$77
Name SquadPos: 'Tournament Setup'!$C$56:$C$59
Name SquadPosT: 'Tournament Setup'!$D$56:$D$61
Name TeamNo: 'Squad Listing'!$A$2:$A$552
Name Teams: 'Tournament Setup'!$A$81:$A$94
Name TrapTimes: 'Tournament Setup'!$B$98:$B$107

Sheet Tournament Setup
A1: Events | B1: Tournament Events | C1: Fees
A2: Skeet | B2: X | C2: 40
A3: Trap | B3: X | C3: 40
A4: Sporting Clays | B4: X | C4: 40
A6: Number of Awards | B6: Gold | C6: Silver | D6: Bronze | E6: Total
A7: HAA | B7: =COUNTIFS($B$17:$B$19,">=1") -> 2 | C7: =COUNTIFS($B$17:$B$19,">=2") -> 2 | D7: =COUNTIFS($B$17:$B$19,">=3") -> 0 | E7: =SUM(B7:D7) -> 4
A8: HOA | B8: =COUNTIFS($B$23:$D$25,">=1") -> 6 | C8: =COUNTIFS($B$23:$D$25,">=2") -> 6 | D8: =COUNTIFS($B$23:$D$25,">=3") -> 0 | E8: =SUM(B8:D8) -> 12
A9: Individual Concurrent | B9: =COUNTIFS($B$29:$D$32,">=1")*COUNTIFS($B$2:$B$4,"X") -> 24 | C9: =COUNTIFS($B$29:$D$32,">=2")*COUNTIFS($B$2:$B$4,"X") -> 24 | D9: =COUNTIFS($B$29:$D$32,">=3")*COUNTIFS($B$2:$B$4,"X") -> 24 | E9: =SUM(B9:D9) -> 72
A10: Individual Class | B10: =COUNTIFS($B$38:$D$41,">=1")*COUNTIFS($B$2:$B$4,"X") -> 24 | C10: =COUNTIFS($B$38:$D$41,">=2")*COUNTIFS($B$2:$B$4,"X") -> 24 | D10: =COUNTIFS($B$38:$D$41,">=3")*COUNTIFS($B$2:$B$4,"X") -> 0 | E10: =SUM(B10:D10) -> 48
A11: Team Concurrent | B11: =COUNTIFS($B$46:$B$50,">=1")*3+COUNTIFS($C$46:$C$50,">=1")*5+COUNTIFS($D$46:$D$50,">=1")*3 -> 55 | C11: =COUNTIFS($B$46:$B$50,">=2")*3+COUNTIFS($C$46:$C$50,">=2")*5+COUNTIFS($D$46:$D$50,">=2")*3 -> 55 | D11: =COUNTIFS($B$46:$B$50,">=3")*3+COUNTIFS($C$46:$C$50,">=3")*5+COUNTIFS($D$46:$D$50,">=3")*3 -> 0 | E11: =SUM(B11:D11) -> 110
A12: Collegiate | B12: =COUNTIFS($B$33:$D$33,">=1")*COUNTIFS($B$2:$B$4,"X") -> 3 | C12: =COUNTIFS($B$33:$D$33,">=2")*COUNTIFS($B$2:$B$4,"X") -> 3 | D12: =COUNTIFS($B$33:$D$33,">=3")*COUNTIFS($B$2:$B$4,"X") -> 3 | E12: =SUM(B12:D12) -> 9
A13: Total Medals | B13: =SUM(B8:B12) -> 112 | C13: =SUM(C8:C12) -> 112 | D13: =SUM(D8:D12) -> 27 | E13: =SUM(B13:D13) -> 251
A16: HAA | B16: # of Places
A17: Places for HAA | B17: 0
A18: Places for HAA Men | B18: 2
A19: Places for HAA Lady | B19: 2
A20: Total HAA Places | B20: =SUM(B17:B19) -> 4
A22: HOA Events | B22: # of Skeet Places | C22: # of Trap Places | D22: # of Sporting Places
A23: Places for HOA | B23: 0 | C23: 0 | D23: 0 | E23: You can do HOA, HOA Men, and HOA Lady
A24: Places for HOA Men | B24: 2 | C24: 2 | D24: 2
A25: Places for HOA Lady | B25: 2 | C25: 2 | D25: 2
A26: Total HOA Places | B26: =SUM(B23:B25) -> 4 | C26: =SUM(C23:C25) -> 4 | D26: =SUM(D23:D25) -> 4
A28: Age Concurrent | B28: # of Places | C28: # of Men's Concurrent Places | D28: # of Lady's Concurrent Places
A29: Novice | B29: 0 | C29: 3 | D29: 3
A30: Intermediate | B30: 0 | C30: 3 | D30: 3
A31: Junior Varsity | B31: 0 | C31: 3 | D31: 3
A32: Varsity | B32: 0 | C32: 3 | D32: 3
A33: Collegiate | B33: 3 | C33: 0 | D33: 0
A34: Total Places | B34: =SUM(B29:B33) -> 3 | C34: =SUM(C29:C33) -> 12 | D34: =SUM(D29:D33) -> 12
A35: Total Medals for all Events | B35: =COUNTIFS($B$2:$B$4,"=X")*B34 -> 9 | C35: =COUNTIFS($B$2:$B$4,"=X")*C34 -> 36 | D35: =COUNTIFS($B$2:$B$4,"=X")*D34 -> 36
A37: Shooting Class | B37: # of Places | C37: # of Men's Concurrent Places | D37: # of Lady's Concurrent Places | F37: Skeet | G37: Trap | H37: Sporting Clays
A38: A | B38: 0 | C38: 2 | D38: 2 | F38: 0.9 | G38: 0.9 | H38: 0.85
A39: B | B39: 0 | C39: 2 | D39: 2 | F39: 0.8 | G39: 0.8 | H39: 0.75
A40: C | B40: 0 | C40: 2 | D40: 2 | F40: 0.7 | G40: 0.7 | H40: 0.65
A41: D | B41: 0 | C41: 2 | D41: 2 | F41: 0 | G41: 0 | H41: 0
A42: Total Places | B42: =SUM(B38:B41) -> 0 | C42: =SUM(C38:C41) -> 8 | D42: =SUM(D38:D41) -> 8
A43: Total Medals for all Events | B43: =COUNTIFS($B$2:$B$4,"=X")*B42 -> 0 | C43: =COUNTIFS($B$2:$B$4,"=X")*C42 -> 24 | D43: =COUNTIFS($B$2:$B$4,"=X")*D42 -> 24
A45: Team Concurrent | B45: # of Skeet Places | C45: # of Trap Places | D45: # of Sporting Places
A46: Novice | B46: 2 | C46: 2 | D46: 2
A47: Intermediate | B47: 2 | C47: 2 | D47: 2
...

Sheet Team Setup
A1: Team ID | B1: Team Name | C1: Head Coach | D1: Email | E1: Address | F1: City | G1: State | H1: ZIP | I1: Phone | J1: Team Affiliation
A2: T001 | B2: High Plains Drifters | C2: Tim Wolfe | D2: Tim@example.com | E2: 1234 Rose Lane | F2: Bennett | G2: CO | H2: 80122 | I2: 303-999-1234 | J2: USAYESS
A3: T002 | B3: Rocky Mountain Clay Busters
A4: T003
A5: T004
A6: T005
A7: T006
A8: T007
A9: T008
A10: T009
A11: T010
A12: T011
A13: T012
A14: T013
A15: T014
... A51: T050

Sheet Individual Setup
A1: Shooter ID | B1: First Name | C1: Last Name | D1: Birthdate | E1: Sex | F1: Contact Phone # | G1: Contact Email | H1: Shooting Team | I1: Age Concurrent | J1: Skeet | K1: Trap | L1: Sporting Clays | M1: Skeet Class | N1: Trap Class | O1: Sporting Class
A2: 26-1000 | B2: Bill | C2: LName1 | D2: 40308 | E2: M | F2: 303-425-2425 | G2: Bill@example.com | H2: Brighton Clay Crushers | I2: Junior Varsity | J2: Y | K2: Y | L2: N
A3: 26-1001 | B3: Tom | C3: LName2 | E3: M | H3: Brighton Clay Crushers | I3: Junior Varsity
A4: 26-1002 | B4: Alan | C4: LName3 | E4: M | H4: Brighton Clay Crushers | I4: Junior Varsity
A5: 26-1003 | B5: Joan | C5: LName4 | E5: F | H5: Brighton Clay Crushers | I5: Novice
A6: 26-1004 | B6: Patricia | C6: LName5 | E6: F | H6: Brighton Clay Crushers | I6: Novice
A7: 26-1005 | B7: Rick | C7: LName6 | E7: M | H7: Brighton Clay Crushers | I7: Novice
A8: 26-1006 | B8: Matt | C8: LName7 | E8: M | H8: Brighton Clay Crushers | I8: Varsity
A9: 26-1007 | B9: Trey | C9: LName8 | E9: M | H9: Brighton Clay Crushers | I9: Varsity
A10: 26-1008 | B10: Christy | C10: LName9 | E10: F | H10: Forge Christian Shooting Team | I10: Intermediate
A11: 26-1009 | B11: Steve | C11: LName10 | E11: M | H11: Forge Christian Shooting Team | I11: Intermediate
A12: 26-1010 | B12: Marty | C12: LName11 | E12: M | H12: Forge Christian Shooting Team | I12: Intermediate
A13: 26-1011 | B13: Susan | C13: LName12 | E13: F | H13: Forge Christian Shooting Team | I13: Varsity
A14: 26-1012 | B14: Paul | C14: LName13 | E14: M | H14: Forge Christian Shooting Team | I14: Varsity
... A49: 26-1047 | B49: Dee | C49: LName48 | E49: F | H49: Wiggins Tigers Sporting Club | I49: Novice
A50: 26-1048
A51: 26-1049
A52: 26-1050
A53: 26-1051
A54: 26-1052
A55: 26-1053
A56: 26-1054
A57: 26-1055
A58: 26-1056
A59: 26-1057
A60: 26-1058
A61: 26-1059
... A234: 26-1232

Sheet Shooter-Squad Assignment
A1: Shooter ID | B1: Team | C1: First Name | D1: Last Name | E1: Full Name | F1: Concurrent | G1: Skeet | H1: Concurrent | I1: Squad Position | J1: Shooting Time | K1: Trap | L1: Concurrent | M1: Squad Position | N1: Shooting Time | O1: Sporting Clays | P1: Concurrent | Q1: Squad Position | R1: Shooting Time | S1: Skeet Squad Key | T1: Skeet Squad # | U1: Shooter Key | V1: Trap Shooter Key | W1: Trap Squad Key | X1: Trap Squad # | Y1: Sporting Shooter Key | Z1: Sporting Squad Key | AA1: Sporting Squad #
A2: 24-1004 | B2: =INDEX('Tournament List'!$L:$L,MATCH($A2,'Tournament List'!$A:$A,0)) -> Brighton Clay Crushers | C2: =INDEX('Tournament List'!$B:$B,MATCH($A2,'Tournament List'!$A:$A,0)) -> Matt | D2: =INDEX('Tournament List'!$C:$C,MATCH($A2,'Tournament List'!$A:$A,0)) -> Last Name5 | E2: =IF(C2<>"",C2&" "&D2,"") -> Matt Last Name5 | F2: =INDEX('Tournament List'!$M:$M,MATCH($A2,'Tournament List'!$A:$A,0)) -> Varsity | G2: Skeet | K2: Trap | O2: Sporting Clays | S2: =IF(H2<>"",B2&"-"&H2&"-"&G2,"") | T2: =IFERROR(INDEX('Squad Listing'!$A:$A,MATCH(S2,'Squad Listing'!$B:$B,0)),"") | U2: =IF(H2<>"",T2&"-"&I2,"") | V2: =IF(L2<>"",B2&"-"&L2&"-"&K2&"-Pos"&M2,"") | W2: =IF(L2<>"",B2&"-"&L2&"-"&K2,"") | X2: =IFERROR(INDEX('Squad Listing'!$A:$A,MATCH(W2,'Squad Listing'!$B:$B,0)),"") | Y2: =IF(P2<>"",B2&"-"&P2&"-"&O2&"-Pos"&Q2,"") | Z2: =IF(P2<>"",B2&"-"&P2&"-"&O2,"") | AA2: =IFERROR(INDEX('Squad Listing'!$A:$A,MATCH(Z2,'Squad Listing'!$B:$B,0)),"")
A3: 24-1016 | B3: =INDEX('Tournament List'!$L:$L,MATCH($A3,'Tournament List'!$A:$A,0)) -> Brighton Clay Crushers | C3: =INDEX('Tournament List'!$B:$B,MATCH($A3,'Tournament List'!$A:$A,0)) -> Joan | D3: =INDEX('Tournament List'!$C:$C,MATCH($A3,'Tournament List'!$A:$A,0)) -> Last Name17 | E3: =IF(C3<>"",C3&" "&D3,"") -> Joan Last Name17 | F3: =INDEX('Tournament List'!$M:$M,MATCH($A3,'Tournament List'!$A:$A,0)) -> Novice | G3: Skeet | H3: Novice 1 | I3: 1 | J3: 9:00 | K3: Trap | O3: Sporting Clays | S3: =IF(H3<>"",B3&"-"&H3&"-"&G3,"") -> Brighton Clay Crushers-Novice 1-Skeet | T3: =IFERROR(INDEX('Squad Listing'!$A:$A,MATCH(S3,'Squad Listing'!$B:$B,0)),"") -> 235 | U3: =IF(H3<>"",T3&"-"&I3,"") -> 235-1 | V3: =IF(L3<>"",B3&"-"&L3&"-"&K3&"-Pos"&M3,"") | W3: =IF(L3<>"",B3&"-"&L3&"-"&K3,"") | X3: =IFERROR(INDEX('Squad Listing'!$A:$A,MATCH(W3,'Squad Listing'!$B:$B,0)),"") | Y3: =IF(P3<>"",B3&"-"&P3&"-"&O3&"-Pos"&Q3,"") | Z3: =IF(P3<>"",B3&"-"&P3&"-"&O3,"") | AA3: =IFERROR(INDEX('Squad Listing'!$A:$A,MATCH(Z3,'Squad Listing'!$B:$B,0)),"")
A4: 24-1034 | B4: =INDEX('Tournament List'!$L:$L,MATCH($A4,'Tournament List'!$A:$A,0)) -> Brighton Clay Crushers | C4: =INDEX('Tournament List'!$B:$B,MATCH($A4,'Tournament List'!$A:$A,0)) -> Patricia | D4: =INDEX('Tournament List'!$C:$C,MATCH($A4,'Tournament List'!$A:$A,0)) -> Last Name35 | E4: =IF(C4<>"",C4&" "&D4,"") -> Patricia Last Name35 | F4: =INDEX('Tournament List'!$M:$M,MATCH($A4,'Tournament List'!$A:$A,0)) -> Novice | G4: Skeet | H4: Novice 1 | I4: 2 | J4: 9:00 | K4: Trap | O4: Sporting Clays | S4: =IF(H4<>"",B4&"-"&H4&"-"&G4,"") -> Brighton Clay Crushers-Novice 1-Skeet | T4: =IFERROR(INDEX('Squad Listing'!$A:$A,MATCH(S4,'Squad Listing'!$B:$B,0)),"") -> 235 | U4: =IF(H4<>"",T4&"-"&I4,"") -> 235-2 | V4: =IF(L4<>"",B4&"-"&L4&"-"&K4&"-Pos"&M4,"") | W4: =IF(L4<>"",B4&"-"&L4&"-"&K4,"") | X4: =IFERROR(INDEX('Squad Listing'!$A:$A,MATCH(W4,'Squad Listing'!$B:$B,0)),"") | Y4: =IF(P4<>"",B4&"-"&P4&"-"&O4&"-Pos"&Q4,"") | Z4: =IF(P4<>"",B4&"-"&P4&"-"&O4,"") | AA4: =IFERROR(INDEX('Squad Listing'!$A:$A,MATCH(Z4,'Squad Listing'!$B:$B,0)),"")
A5: 24-1046 | B5: =INDEX('Tournament List'!$L:$L,MATCH($A5,'Tournament List'!$A:$A,0)) -> Brighton Clay Crushers | C5: =INDEX('Tournament List'!$B:$B,MATCH($A5,'Tournament List'!$A:$A,0)) -> Rick | D5: =INDEX('Tournament List'!$C:$C,MATCH($A5,'Tournament List'!$A:$A,0)) -> Last Name47 | E5: =IF(C5<>"",C5&" "&D5,"") -> Rick Last Name47 | F5: =INDEX('Tournament List'!$M:$M,MATCH($A5,'Tournament List'!$A:$A,0)) -> Novice | G5: Skeet | H5: Novice 1 | I5: 3 | J5: 9:00 | K5: Trap | O5: Sporting Clays | S5: =IF(H5<>"",B5&"-"&H5&"-"&G5,"") -> Brighton Clay Crushers-Novice 1-Skeet | T5: =IFERROR(INDEX('Squad Listing'!$A:$A,MATCH(S5,'Squad Listing'!$B:$B,0)),"") -> 235 | U5: =IF(H5<>"",T5&"-"&I5,"") -> 235-3 | V5: =IF(L5<>"",B5&"-"&L5&"-"&K5&"-Pos"&M5,"") | W5: =IF(L5<>"",B5&"-"&L5&"-"&K5,"") | X5: =IFERROR(INDEX('Squad Listing'!$A:$A,MATCH(W5,'Squad Listing'!$B:$B,0)),"") | Y5: =IF(P5<>"",B5&"-"&P5&"-"&O5&"-Pos"&Q5,"") | Z5: =IF(P5<>"",B5&"-"&P5&"-"&O5,"") | AA5: =IFERROR(INDEX('Squad Listing'!$A:$A,MATCH(Z5,'Squad Listing'!$B:$B,0)),"")
A6: 24-1022 | B6: =INDEX('Tournament List'!$L:$L,MATCH($A6,'Tournament List'!$A:$A,0)) -> Brighton Clay Crushers | C6: =INDEX('Tournament List'!$B:$B,MATCH($A6,'Tournament List'!$A:$A,0)) -> Tom | D6: =INDEX('Tournament List'!$C:$C,MATCH($A6,'Tournament List'!$A:$A,0)) -> Last Name23 | E6: =IF(C6<>"",C6&" "&D6,"") -> Tom Last Name23 | F6: =INDEX('Tournament List'!$M:$M,MATCH($A6,'Tournament List'!$A:$A,0)) -> Junior Varsity | G6: Skeet | H6: Junior Varsity 1 | I6: 1 | K6: Trap | O6: Sporting Clays | S6: =IF(H6<>"",B6&"-"&H6&"-"&G6,"") -> Brighton Clay Crushers-Junior Varsity 1-Skeet | T6: =IFERROR(INDEX('Squad Listing'!$A:$A,MATCH(S6,'Squad Listing'!$B:$B,0)),"") -> 232 | U6: =IF(H6<>"",T6&"-"&I6,"") -> 232-1 | V6: =IF(L6<>"",B6&"-"&L6&"-"&K6&"-Pos"&M6,"") | W6: =IF(L6<>"",B6&"-"&L6&"-"&K6,"") | X6: =IFERROR(INDEX('Squad Listing'!$A:$A,MATCH(W6,'Squad Listing'!$B:$B,0)),"") | Y6: =IF(P6<>"",B6&"-"&P6&"-"&O6&"-Pos"&Q6,"") | Z6: =IF(P6<>"",B6&"-"&P6&"-"&O6,"") | AA6: =IFERROR(INDEX('Squad Listing'!$A:$A,MATCH(Z6,'Squad Listing'!$B:$B,0)),"")
A7: 24-1010 | B7: =INDEX('Tournament List'!$L:$L,MATCH($A7,'Tournament List'!$A:$A,0)) -> Brighton Clay Crushers | C7: =INDEX('Tournament List'!$B:$B,MATCH($A7,'Tournament List'!$A:$A,0)) -> Bill | D7: =INDEX('Tournament List'!$C:$C,MATCH($A7,'Tournament List'!$A:$A,0)) -> Last Name11 | E7: =IF(C7<>"",C7&" "&D7,"") -> Bill Last Name11 | F7: =INDEX('Tournament List'!$M:$M,MATCH($A7,'Tournament List'!$A:$A,0)) -> Junior Varsity | G7: Skeet | H7: Junior Varsity 1 | I7: 2 | K7: Trap | O7: Sporting Clays | S7: =IF(H7<>"",B7&"-"&H7&"-"&G7,"") -> Brighton Clay Crushers-Junior Varsity 1-Skeet | T7: =IFERROR(INDEX('Squad Listing'!$A:$A,MATCH(S7,'Squad Listing'!$B:$B,0)),"") -> 232 | U7: =IF(H7<>"",T7&"-"&I7,"") -> 232-2 | V7: =IF(L7<>"",B7&"-"&L7&"-"&K7&"-Pos"&M7,"") | W7: =IF(L7<>"",B7&"-"&L7&"-"&K7,"") | X7: =IFERROR(INDEX('Squad Listing'!$A:$A,MATCH(W7,'Squad Listing'!$B:$B,0)),"") | Y7: =IF(P7<>"",B7&"-"&P7&"-"&O7&"-Pos"&Q7,"") | Z7: =IF(P7<>"",B7&"-"&P7&"-"&O7,"") | AA7: =IFERROR(INDEX('Squad Listing'!$A:$A,MATCH(Z7,'Squad Listing'!$B:$B,0)),"")
A8: 24-1028 | B8: =INDEX('Tournament List'!$L:$L,MATCH($A8,'Tournament List'!$A:$A,0)) -> Brighton Clay Crushers | C8: =INDEX('Tournament List'!$B:$B,MATCH($A8,'Tournament List'!$A:$A,0)) -> Alan | D8: =INDEX('Tournament List'!$C:$C,MATCH($A8,'Tournament List'!$A:$A,0)) -> Last Name29 | E8: =IF(C8<>"",C8&" "&D8,"") -> Alan Last Name29 | F8: =INDEX('Tournament List'!$M:$M,MATCH($A8,'Tournament List'!$A:$A,0)) -> Junior Varsity | G8: Skeet | H8: Junior Varsity 1 | I8: 3 | K8: Trap | O8: Sporting Clays | S8: =IF(H8<>"",B8&"-"&H8&"-"&G8,"") -> Brighton Clay Crushers-Junior Varsity 1-Skeet | T8: =IFERROR(INDEX('Squad Listing'!$A:$A,MATCH(S8,'Squad Listing'!$B:$B,0)),"") -> 232 | U8: =IF(H8<>"",T8&"-"&I8,"") -> 232-3 | V8: =IF(L8<>"",B8&"-"&L8&"-"&K8&"-Pos"&M8,"") | W8: =IF(L8<>"",B8&"-"&L8&"-"&K8,"") | X8: =IFERROR(INDEX('Squad Listing'!$A:$A,MATCH(W8,'Squad Listing'!$B:$B,0)),"") | Y8: =IF(P8<>"",B8&"-"&P8&"-"&O8&"-Pos"&Q8,"") | Z8: =IF(P8<>"",B8&"-"&P8&"-"&O8,"") | AA8: =IFERROR(INDEX('Squad Listing'!$A:$A,MATCH(Z8,'Squad Listing'!$B:$B,0)),"")
A9: 24-1040 | B9: =INDEX('Tournament List'!$L:$L,MATCH($A9,'Tournament List'!$A:$A,0)) -> Brighton Clay Crushers | C9: =INDEX('Tournament List'!$B:$B,MATCH($A9,'Tournament List'!$A:$A,0)) -> Trey | D9: =INDEX('Tournament List'!$C:$C,MATCH($A9,'Tournament List'!$A:$A,0)) -> Last Name41 | E9: =IF(C9<>"",C9&" "&D9,"") -> Trey Last Name41 | F9: =INDEX('Tournament List'!$M:$M,MATCH($A9,'Tournament List'!$A:$A,0)) -> Varsity | G9: Skeet | K9: Trap | O9: Sporting Clays | S9: =IF(H9<>"",B9&"-"&H9&"-"&G9,"") | T9: =IFERROR(INDEX('Squad Listing'!$A:$A,MATCH(S9,'Squad Listing'!$B:$B,0)),"") | U9: =IF(H9<>"",T9&"-"&I9,"") | V9: =IF(L9<>"",B9&"-"&L9&"-"&K9&"-Pos"&M9,"") | W9: =IF(L9<>"",B9&"-"&L9&"-"&K9,"") | X9: =IFERROR(INDEX('Squad Listing'!$A:$A,MATCH(W9,'Squad Listing'!$B:$B,0)),"") | Y9: =IF(P9<>"",B9&"-"&P9&"-"&O9&"-Pos"&Q9,"") | Z9: =IF(P9<>"",B9&"-"&P9&"-"&O9,"") | AA9: =IFERROR(INDEX('Squad Listing'!$A:$A,MATCH(Z9,'Squad Listing'!$B:$B,0)),"")
A10: 24-1009 | B10: =INDEX('Tournament List'!$L:$L,MATCH($A10,'Tournament List'!$A:$A,0)) -> Forge Christian Shooting Team | C10: =INDEX('Tournament List'!$B:$B,MATCH($A10,'Tournament List'!$A:$A,0)) -> Christy | D10: =INDEX('Tournament List'!$C:$C,MATCH($A10,'Tournament List'!$A:$A,0)) -> Last Name10 | E10: =IF(C10<>"",C10&" "&D10,"") -> Christy Last Name10 | F10: =INDEX('Tournament List'!$M:$M,MATCH($A10,'Tournament List'!$A:$A,0)) -> Intermediate | G10: Skeet | H10: Intermediate 1 | I10: 1 | K10: Trap | O10: Sporting Clays | S10: =IF(H10<>"",B10&"-"&H10&"-"&G10,"") -> Forge Christian Shooting Team-Intermediate 1-Skeet | T10: =IFERROR(INDEX('Squad Listing'!$A:$A,MATCH(S10,'Squad Listing'!$B:$B,0)),"") -> 175 | U10: =IF(H10<>"",T10&"-"&I10,"") -> 175-1 | V10: =IF(L10<>"",B10&"-"&L10&"-"&K10&"-Pos"&M10,"") | W10: =IF(L10<>"",B10&"-"&L10&"-"&K10,"") | X10: =IFERROR(INDEX('Squad Listing'!$A:$A,MATCH(W10,'Squad Listing'!$B:$B,0)),"") | Y10: =IF(P10<>"",B10&"-"&P10&"-"&O10&"-Pos"&Q10,"") | Z10: =IF(P10<>"",B10&"-"&P10&"-"&O10,"") | AA10: =IFERROR(INDEX('Squad Listing'!$A:$A,MATCH(Z10,'Squad Listing'!$B:$B,0)),"")
A11: 24-1021 | B11: =INDEX('Tournament List'!$L:$L,MATCH($A11,'Tournament List'!$A:$A,0)) -> Forge Christian Shooting Team | C11: =INDEX('Tournament List'!$B:$B,MATCH($A11,'Tournament List'!$A:$A,0)) -> Steve | D11: =INDEX('Tournament List'!$C:$C,MATCH($A11,'Tournament List'!$A:$A,0)) -> Last Name22 | E11: =IF(C11<>"",C11&" "&D11,"") -> Steve Last Name22 | F11: =INDEX('Tournament List'!$M:$M,MATCH($A11,'Tournament List'!$A:$A,0)) -> Intermediate | G11: Skeet | H11: Intermediate 1 | I11: 2 | K11: Trap | O11: Sporting Clays | S11: =IF(H11<>"",B11&"-"&H11&"-"&G11,"") -> Forge Christian Shooting Team-Intermediate 1-Skeet | T11: =IFERROR(INDEX('Squad Listing'!$A:$A,MATCH(S11,'Squad Listing'!$B:$B,0)),"") -> 175 | U11: =IF(H11<>"",T11&"-"&I11,"") -> 175-2 | V11: =IF(L11<>"",B11&"-"&L11&"-"&K11&"-Pos"&M11,"") | W11: =IF(L11<>"",B11&"-"&L11&"-"&K11,"") | X11: =IFERROR(INDEX('Squad Listing'!$A:$A,MATCH(W11,'Squad Listing'!$B:$B,0)),"") | Y11: =IF(P11<>"",B11&"-"&P11&"-"&O11&"-Pos"&Q11,"") | Z11: =IF(P11<>"",B11&"-"&P11&"-"&O11,"") | AA11: =IFERROR(INDEX('Squad Listing'!$A:$A,MATCH(Z11,'Squad Listing'!$B:$B,0)),"")
A12: 24-1033 | B12: =INDEX('Tournament List'!$L:$L,MATCH($A12,'Tournament List'!$A:$A,0)) -> Forge Christian Shooting Team | C12: =INDEX('Tournament List'!$B:$B,MATCH($A12,'Tournament List'!$A:$A,0)) -> Marty | D12: =INDEX('Tournament List'!$C:$C,MATCH($A12,'Tournament List'!$A:$A,0)) -> Last Name34 | E12: =IF(C12<>"",C12&" "&D12,"") -> Marty Last Name34 | F12: =INDEX('Tournament List'!$M:$M,MATCH($A12,'Tournament List'!$A:$A,0)) -> Intermediate | G12: Skeet | H12: Intermediate 1 | I12: 3 | K12: Trap | O12: Sporting Clays | S12: =IF(H12<>"",B12&"-"&H12&"-"&G12,"") -> Forge Christian Shooting Team-Intermediate 1-Skeet | T12: =IFERROR(INDEX('Squad Listing'!$A:$A,MATCH(S12,'Squad Listing'!$B:$B,0)),"") -> 175 | U12: =IF(H12<>"",T12&"-"&I12,"") -> 175-3 | V12: =IF(L12<>"",B12&"-"&L12&"-"&K12&"-Pos"&M12,"") | W12: =IF(L12<>"",B12&"-"&L12&"-"&K12,"") | X12: =IFERROR(INDEX('Squad Listing'!$A:$A,MATCH(W12,'Squad Listing'!$B:$B,0)),"") | Y12: =IF(P12<>"",B12&"-"&P12&"-"&O12&"-Pos"&Q12,"") | Z12: =IF(P12<>"",B12&"-"&P12&"-"&O12,"") | AA12: =IFERROR(INDEX('Squad Listing'!$A:$A,MATCH(Z12,'Squad Listing'!$B:$B,0)),"")
A13: 24-1045 | B13: =INDEX('Tournament List'!$L:$L,MATCH($A13,'Tournament List'!$A:$A,0)) -> Forge Christian Shooting Team | C13: =INDEX('Tournament List'!$B:$B,MATCH($A13,'Tournament List'!$A:$A,0)) -> Sam | D13: =INDEX('Tournament List'!$C:$C,MATCH($A13,'Tournament List'!$A:$A,0)) -> Last Name46 | E13: =IF(C13<>"",C13&" "&D13,"") -> Sam Last Name46 | F13: =INDEX('Tournament List'!$M:$M,MATCH($A13,'Tournament List'!$A:$A,0)) -> Varsity | G13: Skeet | H13: Varsity 1 | I13: 1 | K13: Trap | O13: Sporting Clays | S13: =IF(H13<>"",B13&"-"&H13&"-"&G13,"") -> Forge Christian Shooting Team-Varsity 1-Skeet | T13: =IFERROR(INDEX('Squad Listing'!$A:$A,MATCH(S13,'Squad Listing'!$B:$B,0)),"") -> 187 | U13: =IF(H13<>"",T13&"-"&I13,"") -> 187-1 | V13: =IF(L13<>"",B13&"-"&L13&"-"&K13&"-Pos"&M13,"") | W13: =IF(L13<>"",B13&"-"&L13&"-"&K13,"") | X13: =IFERROR(INDEX('Squad Listing'!$A:$A,MATCH(W13,'Squad Listing'!$B:$B,0)),"") | Y13: =IF(P13<>"",B13&"-"&P13&"-"&O13&"-Pos"&Q13,"") | Z13: =IF(P13<>"",B13&"-"&P13&"-"&O13,"") | AA13: =IFERROR(INDEX('Squad Listing'!$A:$A,MATCH(Z13,'Squad Listing'!$B:$B,0)),"")
A14: 24-1015 | B14: =INDEX('Tournament List'!$L:$L,MATCH($A14,'Tournament List'!$A:$A,0)) -> Forge Christian Shooting Team | C14: =INDEX('Tournament List'!$B:$B,MATCH($A14,'Tournament List'!$A:$A,0)) -> Paul | D14: =INDEX('Tournament List'!$C:$C,MATCH($A14,'Tournament List'!$A:$A,0)) -> Last Name16 | E14: =IF(C14<>"",C14&" "&D14,"") -> Paul Last Name16 | F14: =INDEX('Tournament List'!$M:$M,MATCH($A14,'Tournament List'!$A:$A,0)) -> Varsity | G14: Skeet | K14: Trap | O14: Sporting Clays | S14: =IF(H14<>"",B14&"-"&H14&"-"&G14,"") | T14: =IFERROR(INDEX('Squad Listing'!$A:$A,MATCH(S14,'Squad Listing'!$B:$B,0)),"") | U14: =IF(H14<>"",T14&"-"&I14,"") | V14: =IF(L14<>"",B14&"-"&L14&"-"&K14&"-Pos"&M14,"") | W14: =IF(L14<>"",B14&"-"&L14&"-"&K14,"") | X14: =IFERROR(INDEX('Squad Listing'!$A:$A,MATCH(W14,'Squad Listing'!$B:$B,0)),"") | Y14: =IF(P14<>"",B14&"-"&P14&"-"&O14&"-Pos"&Q14,"") | Z14: =IF(P14<>"",B14&"-"&P14&"-"&O14,"") | AA14: =IFERROR(INDEX('Squad Listing'!$A:$A,MATCH(Z14,'Squad Listing'!$B:$B,0)),"")
A15: 24-1027 | B15: =INDEX('Tournament List'!$L:$L,MATCH($A15,'Tournament List'!$A:$A,0)) -> Forge Christian Shooting Team | C15: =INDEX('Tournament List'!$B:$B,MATCH($A15,'Tournament List'!$A:$A,0)) -> Brad | D15: =INDEX('Tournament List'!$C:$C,MATCH($A15,'Tournament List'!$A:$A,0)) -> Last Name28 | E15: =IF(C15<>"",C15&" "&D15,"") -> Brad Last Name28 | F15: =INDEX('Tournament List'!$M:$M,MATCH($A15,'Tournament List'!$A:$A,0)) -> Varsity | G15: Skeet | H15: Varsity 1 | I15: 2 | K15: Trap | O15: Sporting Clays | S15: =IF(H15<>"",B15&"-"&H15&"-"&G15,"") -> Forge Christian Shooting Team-Varsity 1-Skeet | T15: =IFERROR(INDEX('Squad Listing'!$A:$A,MATCH(S15,'Squad Listing'!$B:$B,0)),"") -> 187 | U15: =IF(H15<>"",T15&"-"&I15,"") -> 187-2 | V15: =IF(L15<>"",B15&"-"&L15&"-"&K15&"-Pos"&M15,"") | W15: =IF(L15<>"",B15&"-"&L15&"-"&K15,"") | X15: =IFERROR(INDEX('Squad Listing'!$A:$A,MATCH(W15,'Squad Listing'!$B:$B,0)),"") | Y15: =IF(P15<>"",B15&"-"&P15&"-"&O15&"-Pos"&Q15,"") | Z15: =IF(P15<>"",B15&"-"&P15&"-"&O15,"") | AA15: =IFERROR(INDEX('Squad Listing'!$A:$A,MATCH(Z15,'Squad Listing'!$B:$B,0)),"")
A16: 24-1039 | B16: =INDEX('Tournament List'!$L:$L,MATCH($A16,'Tournament List'!$A:$A,0)) -> Forge Christian Shooting Team | C16: =INDEX('Tournament List'!$B:$B,MATCH($A16,'Tournament List'!$A:$A,0)) -> Troy | D16: =INDEX('Tournament List'!$C:$C,MATCH($A16,'Tournament List'!$A:$A,0)) -> Last Name40 | E16: =IF(C16<>"",C16&" "&D16,"") -> Troy Last Name40 | F16: =INDEX('Tournament List'!$M:$M,MATCH($A16,'Tournament List'!$A:$A,0)) -> Varsity | G16: Skeet | H16: Varsity 1 | I16: 3 | K16: Trap | O16: Sporting Clays | S16: =IF(H16<>"",B16&"-"&H16&"-"&G16,"") -> Forge Christian Shooting Team-Varsity 1-Skeet | T16: =IFERROR(INDEX('Squad Listing'!$A:$A,MATCH(S16,'Squad Listing'!$B:$B,0)),"") -> 187 | U16: =IF(H16<>"",T16&"-"&I16,"") -> 187-3 | V16: =IF(L16<>"",B16&"-"&L16&"-"&K16&"-Pos"&M16,"") | W16: =IF(L16<>"",B16&"-"&L16&"-"&K16,"") | X16: =IFERROR(INDEX('Squad Listing'!$A:$A,MATCH(W16,'Squad Listing'!$B:$B,0)),"") | Y16: =IF(P16<>"",B16&"-"&P16&"-"&O16&"-Pos"&Q16,"") | Z16: =IF(P16<>"",B16&"-"&P16&"-"&O16,"") | AA16: =IFERROR(INDEX('Squad Listing'!$A:$A,MATCH(Z16,'Squad Listing'!$B:$B,0)),"")
A17: 24-1003 | B17: =INDEX('Tournament List'!$L:$L,MATCH($A17,'Tournament List'!$A:$A,0)) -> Forge Christian Shooting Team | C17: =INDEX('Tournament List'!$B:$B,MATCH($A17,'Tournament List'!$A:$A,0)) -> Susan | D17: =INDEX('Tournament List'!$C:$C,MATCH($A17,'Tournament List'!$A:$A,0)) -> Last Name4 | E17: =IF(C17<>"",C17&" "&D17,"") -> Susan Last Name4 | F17: =INDEX('Tournament List'!$M:$M,MATCH($A17,'Tournament List'!$A:$A,0)) -> Varsity | G17: Skeet | K17: Trap | O17: Sporting Clays | S17: =IF(H17<>"",B17&"-"&H17&"-"&G17,"") | T17: =IFERROR(INDEX('Squad Listing'!$A:$A,MATCH(S17,'Squad Listing'!$B:$B,0)),"") | U17: =IF(H17<>"",T17&"-"&I17,"") | V17: =IF(L17<>"",B17&"-"&L17&"-"&K17&"-Pos"&M17,"") | W17: =IF(L17<>"",B17&"-"&L17&"-"&K17,"") | X17: =IFERROR(INDEX('Squad Listing'!$A:$A,MATCH(W17,'Squad Listing'!$B:$B,0)),"") | Y17: =IF(P17<>"",B17&"-"&P17&"-"&O17&"-Pos"&Q17,"") | Z17: =IF(P17<>"",B17&"-"&P17&"-"&O17,"") | AA17: =IFERROR(INDEX('Squad Listing'!$A:$A,MATCH(Z17,'Squad Listing'!$B:$B,0)),"")
A18: 24-1006 | B18: =INDEX('Tournament List'!$L:$L,MATCH($A18,'Tournament List'!$A:$A,0)) -> High Plains Drifters | C18: =INDEX('Tournament List'!$B:$B,MATCH($A18,'Tournament List'!$A:$A,0)) -> Blake | D18: =INDEX('Tournament List'!$C:$C,MATCH($A18,'Tournament List'!$A:$A,0)) -> Last Name7 | E18: =IF(C18<>"",C18&" "&D18,"") -> Blake Last Name7 | F18: =INDEX('Tournament List'!$M:$M,MATCH($A18,'Tournament List'!$A:$A,0)) -> Intermediate | G18: Skeet | H18: Intermediate 1 | I18: 1 | J18: 9:00 | K18: Trap | L18: Open 1 | M18: 4 | N18: 11:00 | O18: Sporting Clays | S18: =IF(H18<>"",B18&"-"&H18&"-"&G18,"") -> High Plains Drifters-Intermediate 1-Skeet | T18: =IFERROR(INDEX('Squad Listing'!$A:$A,MATCH(S18,'Squad Listing'!$B:$B,0)),"") -> 13 | U18: =IF(H18<>"",T18&"-"&I18,"") -> 13-1 | V18: =IF(L18<>"",B18&"-"&L18&"-"&K18&"-Pos"&M18,"") -> High Plains Drifters-Open 1-Trap-Pos4 | W18: =IF(L18<>"",B18&"-"&L18&"-"&K18,"") -> High Plains Drifters-Open 1-Trap | X18: =IFERROR(INDEX('Squad Listing'!$A:$A,MATCH(W18,'Squad Listing'!$B:$B,0)),"") -> 40 | Y18: =IF(P18<>"",B18&"-"&P18&"-"&O18&"-Pos"&Q18,"") | Z18: =IF(P18<>"",B18&"-"&P18&"-"&O18,"") | AA18: =IFERROR(INDEX('Squad Listing'!$A:$A,MATCH(Z18,'Squad Listing'!$B:$B,0)),"")
A19: 24-1030 | B19: =INDEX('Tournament List'!$L:$L,MATCH($A19,'Tournament List'!$A:$A,0)) -> High Plains Drifters | C19: =INDEX('Tournament List'!$B:$B,MATCH($A19,'Tournament List'!$A:$A,0)) -> Shelly | D19: =INDEX('Tournament List'!$C:$C,MATCH($A19,'Tournament List'!$A:$A,0)) -> Last Name31 | E19: =IF(C19<>"",C19&" "&D19,"") -> Shelly Last Name31 | F19: =INDEX('Tournament List'!$M:$M,MATCH($A19,'Tournament List'!$A:$A,0)) -> Intermediate | G19: Skeet | H19: Intermediate 1 | I19: 2 | J19: 9:00 | K19: Trap | L19: Open 1 | M19: 5 | N19: 11:00 | O19: Sporting Clays | S19: =IF(H19<>"",B19&"-"&H19&"-"&G19,"") -> High Plains Drifters-Intermediate 1-Skeet | T19: =IFERROR(INDEX('Squad Listing'!$A:$A,MATCH(S19,'Squad Listing'!$B:$B,0)),"") -> 13 | U19: =IF(H19<>"",T19&"-"&I19,"") -> 13-2 | V19: =IF(L19<>"",B19&"-"&L19&"-"&K19&"-Pos"&M19,"") -> High Plains Drifters-Open 1-Trap-Pos5 | W19: =IF(L19<>"",B19&"-"&L19&"-"&K19,"") -> High Plains Drifters-Open 1-Trap | X19: =IFERROR(INDEX('Squad Listing'!$A:$A,MATCH(W19,'Squad Listing'!$B:$B,0)),"") -> 40 | Y19: =IF(P19<>"",B19&"-"&P19&"-"&O19&"-Pos"&Q19,"") | Z19: =IF(P19<>"",B19&"-"&P19&"-"&O19,"") | AA19: =IFERROR(INDEX('Squad Listing'!$A:$A,MATCH(Z19,'Squad Listing'!$B:$B,0)),"")
A20: 24-1042 | B20: =INDEX('Tournament List'!$L:$L,MATCH($A20,'Tournament List'!$A:$A,0)) -> High Plains Drifters | C20: =INDEX('Tournament List'!$B:$B,MATCH($A20,'Tournament List'!$A:$A,0)) -> Terry | D20: =INDEX('Tournament List'!$C:$C,MATCH($A20,'Tournament List'!$A:$A,0)) -> Last Name43 | E20: =IF(C20<>"",C20&" "&D20,"") -> Terry Last Name43 | F20: =INDEX('Tournament List'!$M:$M,MATCH($A20,'Tournament List'!$A:$A,0)) -> Intermediate | G20: Skeet | H20: Intermediate 1 | I20: 3 | J20: 9:00 | K20: Trap | O20: Sporting Clays | P20: Open 1 | Q20: 1 | S20: =IF(H20<>"",B20&"-"&H20&"-"&G20,"") -> High Plains Drifters-Intermediate 1-Skeet | T20: =IFERROR(INDEX('Squad Listing'!$A:$A,MATCH(S20,'Squad Listing'!$B:$B,0)),"") -> 13 | U20: =IF(H20<>"",T20&"-"&I20,"") -> 13-3 | V20: =IF(L20<>"",B20&"-"&L20&"-"&K20&"-Pos"&M20,"") | W20: =IF(L20<>"",B20&"-"&L20&"-"&K20,"") | X20: =IFERROR(INDEX('Squad Listing'!$A:$A,MATCH(W20,'Squad Listing'!$B:$B,0)),"") | Y20: =IF(P20<>"",B20&"-"&P20&"-"&O20&"-Pos"&Q20,"") -> High Plains Drifters-Open 1-Sporting Clays-Pos1 | Z20: =IF(P20<>"",B20&"-"&P20&"-"&O20,"") -> High Plains Drifters-Open 1-Sporting Clays | AA20: =IFERROR(INDEX('Squad Listing'!$A:$A,MATCH(Z20,'Squad Listing'!$B:$B,0)),"") -> 58
A21: 24-1012 | B21: =INDEX('Tournament List'!$L:$L,MATCH($A21,'Tournament List'!$A:$A,0)) -> High Plains Drifters | C21: =INDEX('Tournament List'!$B:$B,MATCH($A21,'Tournament List'!$A:$A,0)) -> Bruce | D21: =INDEX('Tournament List'!$C:$C,MATCH($A21,'Tournament List'!$A:$A,0)) -> Last Name13 | E21: =IF(C21<>"",C21&" "&D21,"") -> Bruce Last Name13 | F21: =INDEX('Tournament List'!$M:$M,MATCH($A21,'Tournament List'!$A:$A,0)) -> Junior Varsity | G21: Skeet | K21: Trap | O21: Sporting Clays | P21: Open 1 | Q21: 2 | S21: =IF(H21<>"",B21&"-"&H21&"-"&G21,"") | T21: =IFERROR(INDEX('Squad Listing'!$A:$A,MATCH(S21,'Squad Listing'!$B:$B,0)),"") | U21: =IF(H21<>"",T21&"-"&I21,"") | V21: =IF(L21<>"",B21&"-"&L21&"-"&K21&"-Pos"&M21,"") | W21: =IF(L21<>"",B21&"-"&L21&"-"&K21,"") | X21: =IFERROR(INDEX('Squad Listing'!$A:$A,MATCH(W21,'Squad Listing'!$B:$B,0)),"") | Y21: =IF(P21<>"",B21&"-"&P21&"-"&O21&"-Pos"&Q21,"") -> High Plains Drifters-Open 1-Sporting Clays-Pos2 | Z21: =IF(P21<>"",B21&"-"&P21&"-"&O21,"") -> High Plains Drifters-Open 1-Sporting Clays | AA21: =IFERROR(INDEX('Squad Listing'!$A:$A,MATCH(Z21,'Squad Listing'!$B:$B,0)),"") -> 58
A22: 24-1000 | B22: =INDEX('Tournament List'!$L:$L,MATCH($A22,'Tournament List'!$A:$A,0)) -> High Plains Drifters | C22: =INDEX('Tournament List'!$B:$B,MATCH($A22,'Tournament List'!$A:$A,0)) -> Jason | D22: =INDEX('Tournament List'!$C:$C,MATCH($A22,'Tournament List'!$A:$A,0)) -> Last Name1 | E22: =IF(C22<>"",C22&" "&D22,"") -> Jason Last Name1 | F22: =INDEX('Tournament List'!$M:$M,MATCH($A22,'Tournament List'!$A:$A,0)) -> Novice | G22: Skeet | K22: Trap | O22: Sporting Clays | P22: Open 1 | Q22: 3 | S22: =IF(H22<>"",B22&"-"&H22&"-"&G22,"") | T22: =IFERROR(INDEX('Squad Listing'!$A:$A,MATCH(S22,'Squad Listing'!$B:$B,0)),"") | U22: =IF(H22<>"",T22&"-"&I22,"") | V22: =IF(L22<>"",B22&"-"&L22&"-"&K22&"-Pos"&M22,"") | W22: =IF(L22<>"",B22&"-"&L22&"-"&K22,"") | X22: =IFERROR(INDEX('Squad Listing'!$A:$A,MATCH(W22,'Squad Listing'!$B:$B,0)),"") | Y22: =IF(P22<>"",B22&"-"&P22&"-"&O22&"-Pos"&Q22,"") -> High Plains Drifters-Open 1-Sporting Clays-Pos3 | Z22: =IF(P22<>"",B22&"-"&P22&"-"&O22,"") -> High Plains Drifters-Open 1-Sporting Clays | AA22: =IFERROR(INDEX('Squad Listing'!$A:$A,MATCH(Z22,'Squad Listing'!$B:$B,0)),"") -> 58
A23: 24-1018 | B23: =INDEX('Tournament List'!$L:$L,MATCH($A23,'Tournament List'!$A:$A,0)) -> High Plains Drifters | C23: =INDEX('Tournament List'!$B:$B,MATCH($A23,'Tournament List'!$A:$A,0)) -> Jack | D23: =INDEX('Tournament List'!$C:$C,MATCH($A23,'Tournament List'!$A:$A,0)) -> Last Name19 | E23: =IF(C23<>"",C23&" "&D23,"") -> Jack Last Name19 | F23: =INDEX('Tournament List'!$M:$M,MATCH($A23,'Tournament List'!$A:$A,0)) -> Varsity | G23: Skeet | H23: Varsity 1 | I23: 1 | J23: 9:00 | K23: Trap | L23: Open 1 | M23: 1 | N23: 11:00 | O23: Sporting Clays | P23: Varsity 1 | Q23: 2 | S23: =IF(H23<>"",B23&"-"&H23&"-"&G23,"") -> High Plains Drifters-Varsity 1-Skeet | T23: =IFERROR(INDEX('Squad Listing'!$A:$A,MATCH(S23,'Squad Listing'!$B:$B,0)),"") -> 25 | U23: =IF(H23<>"",T23&"-"&I23,"") -> 25-1 | V23: =IF(L23<>"",B23&"-"&L23&"-"&K23&"-Pos"&M23,"") -> High Plains Drifters-Open 1-Trap-Pos1 | W23: =IF(L23<>"",B23&"-"&L23&"-"&K23,"") -> High Plains Drifters-Open 1-Trap | X23: =IFERROR(INDEX('Squad Listing'!$A:$A,MATCH(W23,'Squad Listing'!$B:$B,0)),"") -> 40 | Y23: =IF(P23<>"",B23&"-"&P23&"-"&O23&"-Pos"&Q23,"") -> High Plains Drifters-Varsity 1-Sporting Clays-Pos2 | Z23: =IF(P23<>"",B23&"-"&P23&"-"&O23,"") -> High Plains Drifters-Varsity 1-Sporting Clays | AA23: =IFERROR(INDEX('Squad Listing'!$A:$A,MATCH(Z23,'Squad Listing'!$B:$B,0)),"") -> 61
A24: 24-1024 | B24: =INDEX('Tournament List'!$L:$L,MATCH($A24,'Tournament List'!$A:$A,0)) -> High Plains Drifters | C24: =INDEX('Tournament List'!$B:$B,MATCH($A24,'Tournament List'!$A:$A,0)) -> Harry | D24: =INDEX('Tournament List'!$C:$C,MATCH($A24,'Tournament List'!$A:$A,0)) -> Last Name25 | E24: =IF(C24<>"",C24&" "&D24,"") -> Harry Last Name25 | F24: =INDEX('Tournament List'!$M:$M,MATCH($A24,'Tournament List'!$A:$A,0)) -> Varsity | G24: Skeet | H24: Varsity 1 | I24: 2 | J24: 9:00 | K24: Trap | L24: Open 1 | M24: 2 | N24: 11:00 | O24: Sporting Clays | P24: Varsity 1 | Q24: 1 | S24: =IF(H24<>"",B24&"-"&H24&"-"&G24,"") -> High Plains Drifters-Varsity 1-Skeet | T24: =IFERROR(INDEX('Squad Listing'!$A:$A,MATCH(S24,'Squad Listing'!$B:$B,0)),"") -> 25 | U24: =IF(H24<>"",T24&"-"&I24,"") -> 25-2 | V24: =IF(L24<>"",B24&"-"&L24&"-"&K24&"-Pos"&M24,"") -> High Plains Drifters-Open 1-Trap-Pos2 | W24: =IF(L24<>"",B24&"-"&L24&"-"&K24,"") -> High Plains Drifters-Open 1-Trap | X24: =IFERROR(INDEX('Squad Listing'!$A:$A,MATCH(W24,'Squad Listing'!$B:$B,0)),"") -> 40 | Y24: =IF(P24<>"",B24&"-"&P24&"-"&O24&"-Pos"&Q24,"") -> High Plains Drifters-Varsity 1-Sporting Clays-Pos1 | Z24: =IF(P24<>"",B24&"-"&P24&"-"&O24,"") -> High Plains Drifters-Varsity 1-Sporting Clays | AA24: =IFERROR(INDEX('Squad Listing'!$A:$A,MATCH(Z24,'Squad Listing'!$B:$B,0)),"") -> 61
A25: 24-1036 | B25: =INDEX('Tournament List'!$L:$L,MATCH($A25,'Tournament List'!$A:$A,0)) -> High Plains Drifters | C25: =INDEX('Tournament List'!$B:$B,MATCH($A25,'Tournament List'!$A:$A,0)) -> Will | D25: =INDEX('Tournament List'!$C:$C,MATCH($A25,'Tournament List'!$A:$A,0)) -> Last Name37 | E25: =IF(C25<>"",C25&" "&D25,"") -> Will Last Name37 | F25: =INDEX('Tournament List'!$M:$M,MATCH($A25,'Tournament List'!$A:$A,0)) -> Varsity | G25: Skeet | H25: Varsity 1 | I25: 3 | J25: 9:00 | K25: Trap | L25: Open 1 | M25: 3 | N25: 11:00 | O25: Sporting Clays | P25: Varsity 1 | Q25: 3 | S25: =IF(H25<>"",B25&"-"&H25&"-"&G25,"") -> High Plains Drifters-Varsity 1-Skeet | T25: =IFERROR(INDEX('Squad Listing'!$A:$A,MATCH(S25,'Squad Listing'!$B:$B,0)),"") -> 25 | U25: =IF(H25<>"",T25&"-"&I25,"") -> 25-3 | V25: =IF(L25<>"",B25&"-"&L25&"-"&K25&"-Pos"&M25,"") -> High Plains Drifters-Open 1-Trap-Pos3 | W25: =IF(L25<>"",B25&"-"&L25&"-"&K25,"") -> High Plains Drifters-Open 1-Trap | X25: =IFERROR(INDEX('Squad Listing'!$A:$A,MATCH(W25,'Squad Listing'!$B:$B,0)),"") -> 40 | Y25: =IF(P25<>"",B25&"-"&P25&"-"&O25&"-Pos"&Q25,"") -> High Plains Drifters-Varsity 1-Sporting Clays-Pos3 | Z25: =IF(P25<>"",B25&"-"&P25&"-"&O25,"") -> High Plains Drifters-Varsity 1-Sporting Clays | AA25: =IFERROR(INDEX('Squad Listing'!$A:$A,MATCH(Z25,'Squad Listing'!$B:$B,0)),"") -> 61
A26: 24-1011 | B26: =INDEX('Tournament List'!$L:$L,MATCH($A26,'Tournament List'!$A:$A,0)) -> Littleton Target Masters | C26: =INDEX('Tournament List'!$B:$B,MATCH($A26,'Tournament List'!$A:$A,0)) -> Bob | D26: =INDEX('Tournament List'!$C:$C,MATCH($A26,'Tournament List'!$A:$A,0)) -> Last Name12 | E26: =IF(C26<>"",C26&" "&D26,"") -> Bob Last Name12 | F26: =INDEX('Tournament List'!$M:$M,MATCH($A26,'Tournament List'!$A:$A,0)) -> Collegiate | G26: Skeet | H26: Collegiate 1 | I26: 1 | K26: Trap | O26: Sporting Clays | S26: =IF(H26<>"",B26&"-"&H26&"-"&G26,"") -> Littleton Target Masters-Collegiate 1-Skeet | T26: =IFERROR(INDEX('Squad Listing'!$A:$A,MATCH(S26,'Squad Listing'!$B:$B,0)),"") -> 280 | U26: =IF(H26<>"",T26&"-"&I26,"") -> 280-1 | V26: =IF(L26<>"",B26&"-"&L26&"-"&K26&"-Pos"&M26,"") | W26: =IF(L26<>"",B26&"-"&L26&"-"&K26,"") | X26: =IFERROR(INDEX('Squad Listing'!$A:$A,MATCH(W26,'Squad Listing'!$B:$B,0)),"") | Y26: =IF(P26<>"",B26&"-"&P26&"-"&O26&"-Pos"&Q26,"") | Z26: =IF(P26<>"",B26&"-"&P26&"-"&O26,"") | AA26: =IFERROR(INDEX('Squad Listing'!$A:$A,MATCH(Z26,'Squad Listing'!$B:$B,0)),"")
A27: 24-1017 | B27: =INDEX('Tournament List'!$L:$L,MATCH($A27,'Tournament List'!$A:$A,0)) -> Littleton Target Masters | C27: =INDEX('Tournament List'!$B:$B,MATCH($A27,'Tournament List'!$A:$A,0)) -> Jill | D27: =INDEX('Tournament List'!$C:$C,MATCH($A27,'Tournament List'!$A:$A,0)) -> Last Name18 | E27: =IF(C27<>"",C27&" "&D27,"") -> Jill Last Name18 | F27: =INDEX('Tournament List'!$M:$M,MATCH($A27,'Tournament List'!$A:$A,0)) -> Collegiate | G27: Skeet | H27: Collegiate 1 | I27: 2 | K27: Trap | O27: Sporting Clays | S27: =IF(H27<>"",B27&"-"&H27&"-"&G27,"") -> Littleton Target Masters-Collegiate 1-Skeet | T27: =IFERROR(INDEX('Squad Listing'!$A:$A,MATCH(S27,'Squad Listing'!$B:$B,0)),"") -> 280 | U27: =IF(H27<>"",T27&"-"&I27,"") -> 280-2 | V27: =IF(L27<>"",B27&"-"&L27&"-"&K27&"-Pos"&M27,"") | W27: =IF(L27<>"",B27&"-"&L27&"-"&K27,"") | X27: =IFERROR(INDEX('Squad Listing'!$A:$A,MATCH(W27,'Squad Listing'!$B:$B,0)),"") | Y27: =IF(P27<>"",B27&"-"&P27&"-"&O27&"-Pos"&Q27,"") | Z27: =IF(P27<>"",B27&"-"&P27&"-"&O27,"") | AA27: =IFERROR(INDEX('Squad Listing'!$A:$A,MATCH(Z27,'Squad Listing'!$B:$B,0)),"")
A28: 24-1029 | B28: =INDEX('Tournament List'!$L:$L,MATCH($A28,'Tournament List'!$A:$A,0)) -> Littleton Target Masters | C28: =INDEX('Tournament List'!$B:$B,MATCH($A28,'Tournament List'!$A:$A,0)) -> Judy | D28: =INDEX('Tournament List'!$C:$C,MATCH($A28,'Tournament List'!$A:$A,0)) -> Last Name30 | E28: =IF(C28<>"",C28&" "&D28,"") -> Judy Last Name30 | F28: =INDEX('Tournament List'!$M:$M,MATCH($A28,'Tournament List'!$A:$A,0)) -> Collegiate | G28: Skeet | H28: Collegiate 1 | I28: 3 | K28: Trap | O28: Sporting Clays | S28: =IF(H28<>"",B28&"-"&H28&"-"&G28,"") -> Littleton Target Masters-Collegiate 1-Skeet | T28: =IFERROR(INDEX('Squad Listing'!$A:$A,MATCH(S28,'Squad Listing'!$B:$B,0)),"") -> 280 | U28: =IF(H28<>"",T28&"-"&I28,"") -> 280-3 | V28: =IF(L28<>"",B28&"-"&L28&"-"&K28&"-Pos"&M28,"") | W28: =IF(L28<>"",B28&"-"&L28&"-"&K28,"") | X28: =IFERROR(INDEX('Squad Listing'!$A:$A,MATCH(W28,'Squad Listing'!$B:$B,0)),"") | Y28: =IF(P28<>"",B28&"-"&P28&"-"&O28&"-Pos"&Q28,"") | Z28: =IF(P28<>"",B28&"-"&P28&"-"&O28,"") | AA28: =IFERROR(INDEX('Squad Listing'!$A:$A,MATCH(Z28,'Squad Listing'!$B:$B,0)),"")
A29: 24-1041 | B29: =INDEX('Tournament List'!$L:$L,MATCH($A29,'Tournament List'!$A:$A,0)) -> Littleton Target Masters | C29: =INDEX('Tournament List'!$B:$B,MATCH($A29,'Tournament List'!$A:$A,0)) -> Owen | D29: =INDEX('Tournament List'!$C:$C,MATCH($A29,'Tournament List'!$A:$A,0)) -> Last Name42 | E29: =IF(C29<>"",C29&" "&D29,"") -> Owen Last Name42 | F29: =INDEX('Tournament List'!$M:$M,MATCH($A29,'Tournament List'!$A:$A,0)) -> Novice | G29: Skeet | H29: Novice 1 | I29: 3 | K29: Trap | O29: Sporting Clays | S29: =IF(H29<>"",B29&"-"&H29&"-"&G29,"") -> Littleton Target Masters-Novice 1-Skeet | T29: =IFERROR(INDEX('Squad Listing'!$A:$A,MATCH(S29,'Squad Listing'!$B:$B,0)),"") -> 289 | U29: =IF(H29<>"",T29&"-"&I29,"") -> 289-3 | V29: =IF(L29<>"",B29&"-"&L29&"-"&K29&"-Pos"&M29,"") | W29: =IF(L29<>"",B29&"-"&L29&"-"&K29,"") | X29: =IFERROR(INDEX('Squad Listing'!$A:$A,MATCH(W29,'Squad Listing'!$B:$B,0)),"") | Y29: =IF(P29<>"",B29&"-"&P29&"-"&O29&"-Pos"&Q29,"") | Z29: =IF(P29<>"",B29&"-"&P29&"-"&O29,"") | AA29: =IFERROR(INDEX('Squad Listing'!$A:$A,MATCH(Z29,'Squad Listing'!$B:$B,0)),"")
A30: 24-1005 | B30: =INDEX('Tournament List'!$L:$L,MATCH($A30,'Tournament List'!$A:$A,0)) -> Littleton Target Masters | C30: =INDEX('Tournament List'!$B:$B,MATCH($A30,'Tournament List'!$A:$A,0)) -> Ben | D30: =INDEX('Tournament List'!$C:$C,MATCH($A30,'Tournament List'!$A:$A,0)) -> Last Name6 | E30: =IF(C30<>"",C30&" "&D30,"") -> Ben Last Name6 | F30: =INDEX('Tournament List'!$M:$M,MATCH($A30,'Tournament List'!$A:$A,0)) -> Novice | G30: Skeet | H30: Novice 1 | I30: 2 | K30: Trap | O30: Sporting Clays | S30: =IF(H30<>"",B30&"-"&H30&"-"&G30,"") -> Littleton Target Masters-Novice 1-Skeet | T30: =IFERROR(INDEX('Squad Listing'!$A:$A,MATCH(S30,'Squad Listing'!$B:$B,0)),"") -> 289 | U30: =IF(H30<>"",T30&"-"&I30,"") -> 289-2 | V30: =IF(L30<>"",B30&"-"&L30&"-"&K30&"-Pos"&M30,"") | W30: =IF(L30<>"",B30&"-"&L30&"-"&K30,"") | X30: =IFERROR(INDEX('Squad Listing'!$A:$A,MATCH(W30,'Squad Listing'!$B:$B,0)),"") | Y30: =IF(P30<>"",B30&"-"&P30&"-"&O30&"-Pos"&Q30,"") | Z30: =IF(P30<>"",B30&"-"&P30&"-"&O30,"") | AA30: =IFERROR(INDEX('Squad Listing'!$A:$A,MATCH(Z30,'Squad Listing'!$B:$B,0)),"")
A31: 24-1035 | B31: =INDEX('Tournament List'!$L:$L,MATCH($A31,'Tournament List'!$A:$A,0)) -> Littleton Target Masters | C31: =INDEX('Tournament List'!$B:$B,MATCH($A31,'Tournament List'!$A:$A,0)) -> Randy | D31: =INDEX('Tournament List'!$C:$C,MATCH($A31,'Tournament List'!$A:$A,0)) -> Last Name36 | E31: =IF(C31<>"",C31&" "&D31,"") -> Randy Last Name36 | F31: =INDEX('Tournament List'!$M:$M,MATCH($A31,'Tournament List'!$A:$A,0)) -> Novice | G31: Skeet | H31: Novice 1 | I31: 1 | K31: Trap | O31: Sporting Clays | S31: =IF(H31<>"",B31&"-"&H31&"-"&G31,"") -> Littleton Target Masters-Novice 1-Skeet | T31: =IFERROR(INDEX('Squad Listing'!$A:$A,MATCH(S31,'Squad Listing'!$B:$B,0)),"") -> 289 | U31: =IF(H31<>"",T31&"-"&I31,"") -> 289-1 | V31: =IF(L31<>"",B31&"-"&L31&"-"&K31&"-Pos"&M31,"") | W31: =IF(L31<>"",B31&"-"&L31&"-"&K31,"") | X31: =IFERROR(INDEX('Squad Listing'!$A:$A,MATCH(W31,'Squad Listing'!$B:$B,0)),"") | Y31: =IF(P31<>"",B31&"-"&P31&"-"&O31&"-Pos"&Q31,"") | Z31: =IF(P31<>"",B31&"-"&P31&"-"&O31,"") | AA31: =IFERROR(INDEX('Squad Listing'!$A:$A,MATCH(Z31,'Squad Listing'!$B:$B,0)),"")
A32: 24-1047 | B32: =INDEX('Tournament List'!$L:$L,MATCH($A32,'Tournament List'!$A:$A,0)) -> Littleton Target Masters | C32: =INDEX('Tournament List'!$B:$B,MATCH($A32,'Tournament List'!$A:$A,0)) -> Jackson | D32: =INDEX('Tournament List'!$C:$C,MATCH($A32,'Tournament List'!$A:$A,0)) -> Last Name48 | E32: =IF(C32<>"",C32&" "&D32,"") -> Jackson Last Name48 | F32: =INDEX('Tournament List'!$M:$M,MATCH($A32,'Tournament List'!$A:$A,0)) -> Novice | G32: Skeet | K32: Trap | O32: Sporting Clays | S32: =IF(H32<>"",B32&"-"&H32&"-"&G32,"") | T32: =IFERROR(INDEX('Squad Listing'!$A:$A,MATCH(S32,'Squad Listing'!$B:$B,0)),"") | U32: =IF(H32<>"",T32&"-"&I32,"") | V32: =IF(L32<>"",B32&"-"&L32&"-"&K32&"-Pos"&M32,"") | W32: =IF(L32<>"",B32&"-"&L32&"-"&K32,"") | X32: =IFERROR(INDEX('Squad Listing'!$A:$A,MATCH(W32,'Squad Listing'!$B:$B,0)),"") | Y32: =IF(P32<>"",B32&"-"&P32&"-"&O32&"-Pos"&Q32,"") | Z32: =IF(P32<>"",B32&"-"&P32&"-"&O32,"") | AA32: =IFERROR(INDEX('Squad Listing'!$A:$A,MATCH(Z32,'Squad Listing'!$B:$B,0)),"")
A33: 24-1023 | B33: =INDEX('Tournament List'!$L:$L,MATCH($A33,'Tournament List'!$A:$A,0)) -> Littleton Target Masters | C33: =INDEX('Tournament List'!$B:$B,MATCH($A33,'Tournament List'!$A:$A,0)) -> Tim | D33: =INDEX('Tournament List'!$C:$C,MATCH($A33,'Tournament List'!$A:$A,0)) -> Last Name24 | E33: =IF(C33<>"",C33&" "&D33,"") -> Tim Last Name24 | F33: =INDEX('Tournament List'!$M:$M,MATCH($A33,'Tournament List'!$A:$A,0)) -> Novice | G33: Skeet | K33: Trap | O33: Sporting Clays | S33: =IF(H33<>"",B33&"-"&H33&"-"&G33,"") | T33: =IFERROR(INDEX('Squad Listing'!$A:$A,MATCH(S33,'Squad Listing'!$B:$B,0)),"") | U33: =IF(H33<>"",T33&"-"&I33,"") | V33: =IF(L33<>"",B33&"-"&L33&"-"&K33&"-Pos"&M33,"") | W33: =IF(L33<>"",B33&"-"&L33&"-"&K33,"") | X33: =IFERROR(INDEX('Squad Listing'!$A:$A,MATCH(W33,'Squad Listing'!$B:$B,0)),"") | Y33: =IF(P33<>"",B33&"-"&P33&"-"&O33&"-Pos"&Q33,"") | Z33: =IF(P33<>"",B33&"-"&P33&"-"&O33,"") | AA33: =IFERROR(INDEX('Squad Listing'!$A:$A,MATCH(Z33,'Squad Listing'!$B:$B,0)),"")
A34: 24-1019 | B34: =INDEX('Tournament List'!$L:$L,MATCH($A34,'Tournament List'!$A:$A,0)) -> Rocky Mountain Clay Busters | C34: =INDEX('Tournament List'!$B:$B,MATCH($A34,'Tournament List'!$A:$A,0)) -> Chris | D34: =INDEX('Tournament List'!$C:$C,MATCH($A34,'Tournament List'!$A:$A,0)) -> Last Name20 | E34: =IF(C34<>"",C34&" "&D34,"") -> Chris Last Name20 | F34: =INDEX('Tournament List'!$M:$M,MATCH($A34,'Tournament List'!$A:$A,0)) -> Junior Varsity | G34: Skeet | K34: Trap | O34: Sporting Clays | S34: =IF(H34<>"",B34&"-"&H34&"-"&G34,"") | T34: =IFERROR(INDEX('Squad Listing'!$A:$A,MATCH(S34,'Squad Listing'!$B:$B,0)),"") | U34: =IF(H34<>"",T34&"-"&I34,"") | V34: =IF(L34<>"",B34&"-"&L34&"-"&K34&"-Pos"&M34,"") | W34: =IF(L34<>"",B34&"-"&L34&"-"&K34,"") | X34: =IFERROR(INDEX('Squad Listing'!$A:$A,MATCH(W34,'Squad Listing'!$B:$B,0)),"") | Y34: =IF(P34<>"",B34&"-"&P34&"-"&O34&"-Pos"&Q34,"") | Z34: =IF(P34<>"",B34&"-"&P34&"-"&O34,"") | AA34: =IFERROR(INDEX('Squad Listing'!$A:$A,MATCH(Z34,'Squad Listing'!$B:$B,0)),"")
A35: 24-1001 | B35: =INDEX('Tournament List'!$L:$L,MATCH($A35,'Tournament List'!$A:$A,0)) -> Rocky Mountain Clay Busters | C35: =INDEX('Tournament List'!$B:$B,MATCH($A35,'Tournament List'!$A:$A,0)) -> John | D35: =INDEX('Tournament List'!$C:$C,MATCH($A35,'Tournament List'!$A:$A,0)) -> Last Name2 | E35: =IF(C35<>"",C35&" "&D35,"") -> John Last Name2 | F35: =INDEX('Tournament List'!$M:$M,MATCH($A35,'Tournament List'!$A:$A,0)) -> Junior Varsity | G35: Skeet | K35: Trap | O35: Sporting Clays | S35: =IF(H35<>"",B35&"-"&H35&"-"&G35,"") | T35: =IFERROR(INDEX('Squad Listing'!$A:$A,MATCH(S35,'Squad Listing'!$B:$B,0)),"") | U35: =IF(H35<>"",T35&"-"&I35,"") | V35: =IF(L35<>"",B35&"-"&L35&"-"&K35&"-Pos"&M35,"") | W35: =IF(L35<>"",B35&"-"&L35&"-"&K35,"") | X35: =IFERROR(INDEX('Squad Listing'!$A:$A,MATCH(W35,'Squad Listing'!$B:$B,0)),"") | Y35: =IF(P35<>"",B35&"-"&P35&"-"&O35&"-Pos"&Q35,"") | Z35: =IF(P35<>"",B35&"-"&P35&"-"&O35,"") | AA35: =IFERROR(INDEX('Squad Listing'!$A:$A,MATCH(Z35,'Squad Listing'!$B:$B,0)),"")
A36: 24-1007 | B36: =INDEX('Tournament List'!$L:$L,MATCH($A36,'Tournament List'!$A:$A,0)) -> Rocky Mountain Clay Busters | C36: =INDEX('Tournament List'!$B:$B,MATCH($A36,'Tournament List'!$A:$A,0)) -> James | D36: =INDEX('Tournament List'!$C:$C,MATCH($A36,'Tournament List'!$A:$A,0)) -> Last Name8 | E36: =IF(C36<>"",C36&" "&D36,"") -> James Last Name8 | F36: =INDEX('Tournament List'!$M:$M,MATCH($A36,'Tournament List'!$A:$A,0)) -> Junior Varsity | G36: Skeet | H36: Junior Varsity 1 | I36: 2 | K36: Trap | O36: Sporting Clays | S36: =IF(H36<>"",B36&"-"&H36&"-"&G36,"") -> Rocky Mountain Clay Busters-Junior Varsity 1-Skeet | T36: =IFERROR(INDEX('Squad Listing'!$A:$A,MATCH(S36,'Squad Listing'!$B:$B,0)),"") -> 70 | U36: =IF(H36<>"",T36&"-"&I36,"") -> 70-2 | V36: =IF(L36<>"",B36&"-"&L36&"-"&K36&"-Pos"&M36,"") | W36: =IF(L36<>"",B36&"-"&L36&"-"&K36,"") | X36: =IFERROR(INDEX('Squad Listing'!$A:$A,MATCH(W36,'Squad Listing'!$B:$B,0)),"") | Y36: =IF(P36<>"",B36&"-"&P36&"-"&O36&"-Pos"&Q36,"") | Z36: =IF(P36<>"",B36&"-"&P36&"-"&O36,"") | AA36: =IFERROR(INDEX('Squad Listing'!$A:$A,MATCH(Z36,'Squad Listing'!$B:$B,0)),"")
A37: 24-1025 | B37: =INDEX('Tournament List'!$L:$L,MATCH($A37,'Tournament List'!$A:$A,0)) -> Rocky Mountain Clay Busters | C37: =INDEX('Tournament List'!$B:$B,MATCH($A37,'Tournament List'!$A:$A,0)) -> Gary | D37: =INDEX('Tournament List'!$C:$C,MATCH($A37,'Tournament List'!$A:$A,0)) -> Last Name26 | E37: =IF(C37<>"",C37&" "&D37,"") -> Gary Last Name26 | F37: =INDEX('Tournament List'!$M:$M,MATCH($A37,'Tournament List'!$A:$A,0)) -> Junior Varsity | G37: Skeet | H37: Junior Varsity 1 | I37: 1 | K37: Trap | O37: Sporting Clays | S37: =IF(H37<>"",B37&"-"&H37&"-"&G37,"") -> Rocky Mountain Clay Busters-Junior Varsity 1-Skeet | T37: =IFERROR(INDEX('Squad Listing'!$A:$A,MATCH(S37,'Squad Listing'!$B:$B,0)),"") -> 70 | U37: =IF(H37<>"",T37&"-"&I37,"") -> 70-1 | V37: =IF(L37<>"",B37&"-"&L37&"-"&K37&"-Pos"&M37,"") | W37: =IF(L37<>"",B37&"-"&L37&"-"&K37,"") | X37: =IFERROR(INDEX('Squad Listing'!$A:$A,MATCH(W37,'Squad Listing'!$B:$B,0)),"") | Y37: =IF(P37<>"",B37&"-"&P37&"-"&O37&"-Pos"&Q37,"") | Z37: =IF(P37<>"",B37&"-"&P37&"-"&O37,"") | AA37: =IFERROR(INDEX('Squad Listing'!$A:$A,MATCH(Z37,'Squad Listing'!$B:$B,0)),"")
A38: 24-1037 | B38: =INDEX('Tournament List'!$L:$L,MATCH($A38,'Tournament List'!$A:$A,0)) -> Rocky Mountain Clay Busters | C38: =INDEX('Tournament List'!$B:$B,MATCH($A38,'Tournament List'!$A:$A,0)) -> Stuart | D38: =INDEX('Tournament List'!$C:$C,MATCH($A38,'Tournament List'!$A:$A,0)) -> Last Name38 | E38: =IF(C38<>"",C38&" "&D38,"") -> Stuart Last Name38 | F38: =INDEX('Tournament List'!$M:$M,MATCH($A38,'Tournament List'!$A:$A,0)) -> Junior Varsity | G38: Skeet | H38: Junior Varsity 1 | I38: 3 | K38: Trap | O38: Sporting Clays | S38: =IF(H38<>"",B38&"-"&H38&"-"&G38,"") -> Rocky Mountain Clay Busters-Junior Varsity 1-Skeet | T38: =IFERROR(INDEX('Squad Listing'!$A:$A,MATCH(S38,'Squad Listing'!$B:$B,0)),"") -> 70 | U38: =IF(H38<>"",T38&"-"&I38,"") -> 70-3 | V38: =IF(L38<>"",B38&"-"&L38&"-"&K38&"-Pos"&M38,"") | W38: =IF(L38<>"",B38&"-"&L38&"-"&K38,"") | X38: =IFERROR(INDEX('Squad Listing'!$A:$A,MATCH(W38,'Squad Listing'!$B:$B,0)),"") | Y38: =IF(P38<>"",B38&"-"&P38&"-"&O38&"-Pos"&Q38,"") | Z38: =IF(P38<>"",B38&"-"&P38&"-"&O38,"") | AA38: =IFERROR(INDEX('Squad Listing'!$A:$A,MATCH(Z38,'Squad Listing'!$B:$B,0)),"")
A39: 24-1031 | B39: =INDEX('Tournament List'!$L:$L,MATCH($A39,'Tournament List'!$A:$A,0)) -> Rocky Mountain Clay Busters | C39: =INDEX('Tournament List'!$B:$B,MATCH($A39,'Tournament List'!$A:$A,0)) -> Kelly | D39: =INDEX('Tournament List'!$C:$C,MATCH($A39,'Tournament List'!$A:$A,0)) -> Last Name32 | E39: =IF(C39<>"",C39&" "&D39,"") -> Kelly Last Name32 | F39: =INDEX('Tournament List'!$M:$M,MATCH($A39,'Tournament List'!$A:$A,0)) -> Intermediate | G39: Skeet | H39: Intermediate 1 | I39: 3 | K39: Trap | O39: Sporting Clays | S39: =IF(H39<>"",B39&"-"&H39&"-"&G39,"") -> Rocky Mountain Clay Busters-Intermediate 1-Skeet | T39: =IFERROR(INDEX('Squad Listing'!$A:$A,MATCH(S39,'Squad Listing'!$B:$B,0)),"") -> 67 | U39: =IF(H39<>"",T39&"-"&I39,"") -> 67-3 | V39: =IF(L39<>"",B39&"-"&L39&"-"&K39&"-Pos"&M39,"") | W39: =IF(L39<>"",B39&"-"&L39&"-"&K39,"") | X39: =IFERROR(INDEX('Squad Listing'!$A:$A,MATCH(W39,'Squad Listing'!$B:$B,0)),"") | Y39: =IF(P39<>"",B39&"-"&P39&"-"&O39&"-Pos"&Q39,"") | Z39: =IF(P39<>"",B39&"-"&P39&"-"&O39,"") | AA39: =IFERROR(INDEX('Squad Listing'!$A:$A,MATCH(Z39,'Squad Listing'!$B:$B,0)),"")
A40: 24-1043 | B40: =INDEX('Tournament List'!$L:$L,MATCH($A40,'Tournament List'!$A:$A,0)) -> Rocky Mountain Clay Busters | C40: =INDEX('Tournament List'!$B:$B,MATCH($A40,'Tournament List'!$A:$A,0)) -> Trisha | D40: =INDEX('Tournament List'!$C:$C,MATCH($A40,'Tournament List'!$A:$A,0)) -> Last Name44 | E40: =IF(C40<>"",C40&" "&D40,"") -> Trisha Last Name44 | F40: =INDEX('Tournament List'!$M:$M,MATCH($A40,'Tournament List'!$A:$A,0)) -> Intermediate | G40: Skeet | H40: Intermediate 1 | I40: 1 | K40: Trap | O40: Sporting Clays | S40: =IF(H40<>"",B40&"-"&H40&"-"&G40,"") -> Rocky Mountain Clay Busters-Intermediate 1-Skeet | T40: =IFERROR(INDEX('Squad Listing'!$A:$A,MATCH(S40,'Squad Listing'!$B:$B,0)),"") -> 67 | U40: =IF(H40<>"",T40&"-"&I40,"") -> 67-1 | V40: =IF(L40<>"",B40&"-"&L40&"-"&K40&"-Pos"&M40,"") | W40: =IF(L40<>"",B40&"-"&L40&"-"&K40,"") | X40: =IFERROR(INDEX('Squad Listing'!$A:$A,MATCH(W40,'Squad Listing'!$B:$B,0)),"") | Y40: =IF(P40<>"",B40&"-"&P40&"-"&O40&"-Pos"&Q40,"") | Z40: =IF(P40<>"",B40&"-"&P40&"-"&O40,"") | AA40: =IFERROR(INDEX('Squad Listing'!$A:$A,MATCH(Z40,'Squad Listing'!$B:$B,0)),"")
...

Sheet Squad Listing
A1: Squad # | B1: Squad Key | C1: Team Name | D1: Concurrent | E1: Discipline | F1: Participant #1 ID | G1: Participant #1 Name | H1: Participant #2 ID | I1: Participant #2 Name | J1: Participant #3 ID | K1: Participant #3 Name | L1: Participant #4 ID | M1: Participant #4 Name | N1: Participant #5 ID | O1: Participant #5 Name
A2: 10 | B2: =C2&"-"&D2&"-"&E2 -> High Plains Drifters-Collegiate 1-Skeet | C2: High Plains Drifters | D2: Collegiate 1 | E2: Skeet | F2: =IF(E2="Skeet",IFERROR(INDEX('Shooter-Squad Assignment'!$A:$A,MATCH(C2&"-"&D2&"-"&E2&"-Pos1",'Shooter-Squad Assignment'!#REF!,0)),""),IF(E2="Trap",IFERROR(INDEX('Shooter-Squad Assignment'!$A:$A,MATCH(C2&"-"&D2&"-"&E2&"-Pos1",'Shooter-Squad Assignment'!$V:$V,0)),""),IF(E2="Sporting Clays",IFERROR(INDEX('Shooter-Squad Assignment'!$A:$A,MATCH(C2&"-"&D2&"-"&E2&"-Pos1",'Shooter-Squad Assignment'!$Y:$Y,0)),""),""))) | G2: =IF(ISBLANK(F2),"",IFERROR(INDEX('Tournament List'!$D:$D,MATCH(F2,'Tournament List'!$A:$A,0)),"")) | H2: =IF(E2="Skeet",IFERROR(INDEX('Shooter-Squad Assignment'!$A:$A,MATCH(C2&"-"&D2&"-"&E2&"-Pos2",'Shooter-Squad Assignment'!#REF!,0)),""),IF(E2="Trap",IFERROR(INDEX('Shooter-Squad Assignment'!$A:$A,MATCH(C2&"-"&D2&"-"&E2&"-Pos2",'Shooter-Squad Assignment'!$V:$V,0)),""),IF(E2="Sporting Clays",IFERROR(INDEX('Shooter-Squad Assignment'!$A:$A,MATCH(C2&"-"&D2&"-"&E2&"-Pos2",'Shooter-Squad Assignment'!$Y:$Y,0)),""),""))) | I2: =IF(ISBLANK(H2),"",IFERROR(INDEX('Tournament List'!$D:$D,MATCH(H2,'Tournament List'!$A:$A,0)),"")) | J2: =IF(E2="Skeet",IFERROR(INDEX('Shooter-Squad Assignment'!$A:$A,MATCH(C2&"-"&D2&"-"&E2&"-Pos3",'Shooter-Squad Assignment'!#REF!,0)),""),IF(E2="Trap",IFERROR(INDEX('Shooter-Squad Assignment'!$A:$A,MATCH(C2&"-"&D2&"-"&E2&"-Pos3",'Shooter-Squad Assignment'!$V:$V,0)),""),IF(E2="Sporting Clays",IFERROR(INDEX('Shooter-Squad Assignment'!$A:$A,MATCH(C2&"-"&D2&"-"&E2&"-Pos3",'Shooter-Squad Assignment'!$Y:$Y,0)),""),""))) | K2: =IF(ISBLANK(J2),"",IFERROR(INDEX('Tournament List'!$D:$D,MATCH(J2,'Tournament List'!$A:$A,0)),"")) | L2: =IF(E2="Skeet",IFERROR(INDEX('Shooter-Squad Assignment'!$A:$A,MATCH(C2&"-"&D2&"-"&E2&"-Pos4",'Shooter-Squad Assignment'!#REF!,0)),""),IF(E2="Trap",IFERROR(INDEX('Shooter-Squad Assignment'!$A:$A,MATCH(C2&"-"&D2&"-"&E2&"-Pos4",'Shooter-Squad Assignment'!$V:$V,0)),""),IF(E2="Sporting Clays",IFERROR(INDEX('Shooter-Squad Assignment'!$A:$A,MATCH(C2&"-"&D2&"-"&E2&"-Pos4",'Shooter-Squad Assignment'!$Y:$Y,0)),""),""))) | M2: =IF(ISBLANK(L2),"",IFERROR(INDEX('Tournament List'!$D:$D,MATCH(L2,'Tournament List'!$A:$A,0)),"")) | N2: =IF(E2="Skeet",IFERROR(INDEX('Shooter-Squad Assignment'!$A:$A,MATCH(C2&"-"&D2&"-"&E2&"-Pos5",'Shooter-Squad Assignment'!#REF!,0)),""),IF(E2="Trap",IFERROR(INDEX('Shooter-Squad Assignment'!$A:$A,MATCH(C2&"-"&D2&"-"&E2&"-Pos5",'Shooter-Squad Assignment'!$V:$V,0)),""),IF(E2="Sporting Clays",IFERROR(INDEX('Shooter-Squad Assignment'!$A:$A,MATCH(C2&"-"&D2&"-"&E2&"-Pos5",'Shooter-Squad Assignment'!$Y:$Y,0)),""),""))) | O2: =IF(ISBLANK(N2),"",IFERROR(INDEX('Tournament List'!$D:$D,MATCH(N2,'Tournament List'!$A:$A,0)),""))
A3: 11 | B3: =C3&"-"&D3&"-"&E3 -> High Plains Drifters-Collegiate 2-Skeet | C3: High Plains Drifters | D3: Collegiate 2 | E3: Skeet | F3: =IF(E3="Skeet",IFERROR(INDEX('Shooter-Squad Assignment'!$A:$A,MATCH(C3&"-"&D3&"-"&E3&"-Pos1",'Shooter-Squad Assignment'!#REF!,0)),""),IF(E3="Trap",IFERROR(INDEX('Shooter-Squad Assignment'!$A:$A,MATCH(C3&"-"&D3&"-"&E3&"-Pos1",'Shooter-Squad Assignment'!$V:$V,0)),""),IF(E3="Sporting Clays",IFERROR(INDEX('Shooter-Squad Assignment'!$A:$A,MATCH(C3&"-"&D3&"-"&E3&"-Pos1",'Shooter-Squad Assignment'!$Y:$Y,0)),""),""))) | G3: =IF(ISBLANK(F3),"",IFERROR(INDEX('Tournament List'!$D:$D,MATCH(F3,'Tournament List'!$A:$A,0)),"")) | H3: =IF(E3="Skeet",IFERROR(INDEX('Shooter-Squad Assignment'!$A:$A,MATCH(C3&"-"&D3&"-"&E3&"-Pos2",'Shooter-Squad Assignment'!#REF!,0)),""),IF(E3="Trap",IFERROR(INDEX('Shooter-Squad Assignment'!$A:$A,MATCH(C3&"-"&D3&"-"&E3&"-Pos2",'Shooter-Squad Assignment'!$V:$V,0)),""),IF(E3="Sporting Clays",IFERROR(INDEX('Shooter-Squad Assignment'!$A:$A,MATCH(C3&"-"&D3&"-"&E3&"-Pos2",'Shooter-Squad Assignment'!$Y:$Y,0)),""),""))) | I3: =IF(ISBLANK(H3),"",IFERROR(INDEX('Tournament List'!$D:$D,MATCH(H3,'Tournament List'!$A:$A,0)),"")) | J3: =IF(E3="Skeet",IFERROR(INDEX('Shooter-Squad Assignment'!$A:$A,MATCH(C3&"-"&D3&"-"&E3&"-Pos3",'Shooter-Squad Assignment'!#REF!,0)),""),IF(E3="Trap",IFERROR(INDEX('Shooter-Squad Assignment'!$A:$A,MATCH(C3&"-"&D3&"-"&E3&"-Pos3",'Shooter-Squad Assignment'!$V:$V,0)),""),IF(E3="Sporting Clays",IFERROR(INDEX('Shooter-Squad Assignment'!$A:$A,MATCH(C3&"-"&D3&"-"&E3&"-Pos3",'Shooter-Squad Assignment'!$Y:$Y,0)),""),""))) | K3: =IF(ISBLANK(J3),"",IFERROR(INDEX('Tournament List'!$D:$D,MATCH(J3,'Tournament List'!$A:$A,0)),"")) | L3: =IF(E3="Skeet",IFERROR(INDEX('Shooter-Squad Assignment'!$A:$A,MATCH(C3&"-"&D3&"-"&E3&"-Pos4",'Shooter-Squad Assignment'!#REF!,0)),""),IF(E3="Trap",IFERROR(INDEX('Shooter-Squad Assignment'!$A:$A,MATCH(C3&"-"&D3&"-"&E3&"-Pos4",'Shooter-Squad Assignment'!$V:$V,0)),""),IF(E3="Sporting Clays",IFERROR(INDEX('Shooter-Squad Assignment'!$A:$A,MATCH(C3&"-"&D3&"-"&E3&"-Pos4",'Shooter-Squad Assignment'!$Y:$Y,0)),""),""))) | M3: =IF(ISBLANK(L3),"",IFERROR(INDEX('Tournament List'!$D:$D,MATCH(L3,'Tournament List'!$A:$A,0)),"")) | N3: =IF(E3="Skeet",IFERROR(INDEX('Shooter-Squad Assignment'!$A:$A,MATCH(C3&"-"&D3&"-"&E3&"-Pos5",'Shooter-Squad Assignment'!#REF!,0)),""),IF(E3="Trap",IFERROR(INDEX('Shooter-Squad Assignment'!$A:$A,MATCH(C3&"-"&D3&"-"&E3&"-Pos5",'Shooter-Squad Assignment'!$V:$V,0)),""),IF(E3="Sporting Clays",IFERROR(INDEX('Shooter-Squad Assignment'!$A:$A,MATCH(C3&"-"&D3&"-"&E3&"-Pos5",'Shooter-Squad Assignment'!$Y:$Y,0)),""),""))) | O3: =IF(ISBLANK(N3),"",IFERROR(INDEX('Tournament List'!$D:$D,MATCH(N3,'Tournament List'!$A:$A,0)),""))
A4: 12 | B4: =C4&"-"&D4&"-"&E4 -> High Plains Drifters-Collegiate 3-Skeet | C4: High Plains Drifters | D4: Collegiate 3 | E4: Skeet | F4: =IF(E4="Skeet",IFERROR(INDEX('Shooter-Squad Assignment'!$A:$A,MATCH(C4&"-"&D4&"-"&E4&"-Pos1",'Shooter-Squad Assignment'!#REF!,0)),""),IF(E4="Trap",IFERROR(INDEX('Shooter-Squad Assignment'!$A:$A,MATCH(C4&"-"&D4&"-"&E4&"-Pos1",'Shooter-Squad Assignment'!$V:$V,0)),""),IF(E4="Sporting Clays",IFERROR(INDEX('Shooter-Squad Assignment'!$A:$A,MATCH(C4&"-"&D4&"-"&E4&"-Pos1",'Shooter-Squad Assignment'!$Y:$Y,0)),""),""))) | G4: =IF(ISBLANK(F4),"",IFERROR(INDEX('Tournament List'!$D:$D,MATCH(F4,'Tournament List'!$A:$A,0)),"")) | H4: =IF(E4="Skeet",IFERROR(INDEX('Shooter-Squad Assignment'!$A:$A,MATCH(C4&"-"&D4&"-"&E4&"-Pos2",'Shooter-Squad Assignment'!#REF!,0)),""),IF(E4="Trap",IFERROR(INDEX('Shooter-Squad Assignment'!$A:$A,MATCH(C4&"-"&D4&"-"&E4&"-Pos2",'Shooter-Squad Assignment'!$V:$V,0)),""),IF(E4="Sporting Clays",IFERROR(INDEX('Shooter-Squad Assignment'!$A:$A,MATCH(C4&"-"&D4&"-"&E4&"-Pos2",'Shooter-Squad Assignment'!$Y:$Y,0)),""),""))) | I4: =IF(ISBLANK(H4),"",IFERROR(INDEX('Tournament List'!$D:$D,MATCH(H4,'Tournament List'!$A:$A,0)),"")) | J4: =IF(E4="Skeet",IFERROR(INDEX('Shooter-Squad Assignment'!$A:$A,MATCH(C4&"-"&D4&"-"&E4&"-Pos3",'Shooter-Squad Assignment'!#REF!,0)),""),IF(E4="Trap",IFERROR(INDEX('Shooter-Squad Assignment'!$A:$A,MATCH(C4&"-"&D4&"-"&E4&"-Pos3",'Shooter-Squad Assignment'!$V:$V,0)),""),IF(E4="Sporting Clays",IFERROR(INDEX('Shooter-Squad Assignment'!$A:$A,MATCH(C4&"-"&D4&"-"&E4&"-Pos3",'Shooter-Squad Assignment'!$Y:$Y,0)),""),""))) | K4: =IF(ISBLANK(J4),"",IFERROR(INDEX('Tournament List'!$D:$D,MATCH(J4,'Tournament List'!$A:$A,0)),"")) | L4: =IF(E4="Skeet",IFERROR(INDEX('Shooter-Squad Assignment'!$A:$A,MATCH(C4&"-"&D4&"-"&E4&"-Pos4",'Shooter-Squad Assignment'!#REF!,0)),""),IF(E4="Trap",IFERROR(INDEX('Shooter-Squad Assignment'!$A:$A,MATCH(C4&"-"&D4&"-"&E4&"-Pos4",'Shooter-Squad Assignment'!$V:$V,0)),""),IF(E4="Sporting Clays",IFERROR(INDEX('Shooter-Squad Assignment'!$A:$A,MATCH(C4&"-"&D4&"-"&E4&"-Pos4",'Shooter-Squad Assignment'!$Y:$Y,0)),""),""))) | M4: =IF(ISBLANK(L4),"",IFERROR(INDEX('Tournament List'!$D:$D,MATCH(L4,'Tournament List'!$A:$A,0)),"")) | N4: =IF(E4="Skeet",IFERROR(INDEX('Shooter-Squad Assignment'!$A:$A,MATCH(C4&"-"&D4&"-"&E4&"-Pos5",'Shooter-Squad Assignment'!#REF!,0)),""),IF(E4="Trap",IFERROR(INDEX('Shooter-Squad Assignment'!$A:$A,MATCH(C4&"-"&D4&"-"&E4&"-Pos5",'Shooter-Squad Assignment'!$V:$V,0)),""),IF(E4="Sporting Clays",IFERROR(INDEX('Shooter-Squad Assignment'!$A:$A,MATCH(C4&"-"&D4&"-"&E4&"-Pos5",'Shooter-Squad Assignment'!$Y:$Y,0)),""),""))) | O4: =IF(ISBLANK(N4),"",IFERROR(INDEX('Tournament List'!$D:$D,MATCH(N4,'Tournament List'!$A:$A,0)),""))
