Workbook
Name AgeConcurrents: 'Tournament Setup'!$A$32:$A$36
Name Concurrent: 'Tournament Setup'!$A$49:$A$54
Name ShooterID: 'Tournament List'!$A$3:$A$203
Name SkeetTimes: 'Tournament Setup'!$A$108:$A$117
Name SportingTimes: 'Tournament Setup'!$C$108:$C$117
Name SquadConcurrents: 'Tournament Setup'!$A$59:$A$78
Name SquadPos: 'Tournament Setup'!$A$81:$A$84
Name SquadPosT: 'Tournament Setup'!$B$81:$B$86
Name TeamNo: 'Squad Listing'!$A$2:$A$585
Name Teams: 'Tournament Setup'!$A$91:$A$104
Name TrapTimes: 'Tournament Setup'!$B$108:$B$117

Sheet Tournament Setup
A1: Tournament Date | B1: 45677
A4: Events | B4: Tournament Events | C4: Fees
A5: Skeet | B5: X | C5: 40
A6: Trap | B6: X | C6: 40
A7: Sporting Clays | B7: X | C7: 40
A9: Number of Awards | B9: Gold | C9: Silver | D9: Bronze | E9: Total
A10: HAA | B10: =COUNTIFS($B$20:$B$22,">=1") -> 3 | C10: =COUNTIFS($B$20:$B$22,">=2") -> 3 | D10: =COUNTIFS($B$20:$B$22,">=3") -> 3 | E10: =SUM(B10:D10) -> 9
A11: HOA | B11: =COUNTIFS($B$26:$D$28,">=1") -> 8 | C11: =COUNTIFS($B$26:$D$28,">=2") -> 8 | D11: =COUNTIFS($B$26:$D$28,">=3") -> 6 | E11: =SUM(B11:D11) -> 22
A12: Individual Concurrent | B12: =COUNTIFS($B$32:$D$35,">=1")*COUNTIFS($B$5:$B$7,"X") -> 36 | C12: =COUNTIFS($B$32:$D$35,">=2")*COUNTIFS($B$5:$B$7,"X") -> 36 | D12: =COUNTIFS($B$32:$D$35,">=3")*COUNTIFS($B$5:$B$7,"X") -> 36 | E12: =SUM(B12:D12) -> 108
A13: Individual Class | B13: =COUNTIFS($B$41:$D$44,">=1")*COUNTIFS($B$5:$B$7,"X") -> 36 | C13: =COUNTIFS($B$41:$D$44,">=2")*COUNTIFS($B$5:$B$7,"X") -> 36 | D13: =COUNTIFS($B$41:$D$44,">=3")*COUNTIFS($B$5:$B$7,"X") -> 36 | E13: =SUM(B13:D13) -> 108
A14: Team Concurrent | B14: =COUNTIFS($B$49:$B$53,">=1")*3+COUNTIFS($C$49:$C$53,">=1")*5+COUNTIFS($D$49:$D$53,">=1")*3 -> 55 | C14: =COUNTIFS($B$49:$B$53,">=2")*3+COUNTIFS($C$49:$C$53,">=2")*5+COUNTIFS($D$49:$D$53,">=2")*3 -> 55 | D14: =COUNTIFS($B$49:$B$53,">=3")*3+COUNTIFS($C$49:$C$53,">=3")*5+COUNTIFS($D$49:$D$53,">=3")*3 -> 30 | E14: =SUM(B14:D14) -> 140
A15: Collegiate | B15: =COUNTIFS($B$36:$D$36,">=1")*COUNTIFS($B$5:$B$7,"X") -> 9 | C15: =COUNTIFS($B$36:$D$36,">=2")*COUNTIFS($B$5:$B$7,"X") -> 9 | D15: =COUNTIFS($B$36:$D$36,">=3")*COUNTIFS($B$5:$B$7,"X") -> 9 | E15: =SUM(B15:D15) -> 27
A16: Total Medals | B16: =SUM(B11:B15) -> 144 | C16: =SUM(C11:C15) -> 144 | D16: =SUM(D11:D15) -> 117 | E16: =SUM(B16:D16) -> 405
A19: HAA | B19: # of Places
A20: Places for HAA | B20: 3
A21: Places for HAA Men | B21: 3
A22: Places for HAA Lady | B22: 3
A23: Total HAA Places | B23: =SUM(B20:B22) -> 9
A25: HOA Events | B25: # of Skeet Places | C25: # of Trap Places | D25: # of Sporting Places
A26: Places for HOA | B26: 3 | C26: 0 | D26: 3 | E26: You can do HOA, HOA Men, and HOA Lady
A27: Places for HOA Men | B27: 3 | C27: 2 | D27: 3
A28: Places for HOA Lady | B28: 3 | C28: 2 | D28: 3
A29: Total HOA Places | B29: =SUM(B26:B28) -> 9 | C29: =SUM(C26:C28) -> 4 | D29: =SUM(D26:D28) -> 9
A31: Age Concurrent | B31: # of Places | C31: # of Men's Concurrent Places | D31: # of Lady's Concurrent Places
A32: Novice | B32: 3 | C32: 3 | D32: 3
A33: Intermediate | B33: 3 | C33: 3 | D33: 3
A34: Junior Varsity | B34: 3 | C34: 3 | D34: 3
A35: Varsity | B35: 3 | C35: 3 | D35: 3
A36: Collegiate | B36: 3 | C36: 3 | D36: 3
A37: Total Places | B37: =SUM(B32:B36) -> 15 | C37: =SUM(C32:C36) -> 15 | D37: =SUM(D32:D36) -> 15
A38: Total Medals for all Events | B38: =COUNTIFS($B$5:$B$7,"=X")*B37 -> 45 | C38: =COUNTIFS($B$5:$B$7,"=X")*C37 -> 45 | D38: =COUNTIFS($B$5:$B$7,"=X")*D37 -> 45
A40: Shooting Class | B40: # of Places | C40: # of Men's Concurrent Places | D40: # of Lady's Concurrent Places | F40: Skeet | G40: Trap | H40: Sporting Clays
A41: A | B41: 3 | C41: 3 | D41: 3 | F41: 0.9 | G41: 0.9 | H41: 0.85
A42: B | B42: 3 | C42: 3 | D42: 3 | F42: 0.8 | G42: 0.8 | H42: 0.75
A43: C | B43: 3 | C43: 3 | D43: 3 | F43: 0.7 | G43: 0.7 | H43: 0.65
A44: D | B44: 3 | C44: 3 | D44: 3 | F44: 0 | G44: 0 | H44: 0
A45: Total Places | B45: =SUM(B41:B44) -> 12 | C45: =SUM(C41:C44) -> 12 | D45: =SUM(D41:D44) -> 12
A46: Total Medals for all Events | B46: =COUNTIFS($B$5:$B$7,"=X")*B45 -> 36 | C46: =COUNTIFS($B$5:$B$7,"=X")*C45 -> 36 | D46: =COUNTIFS($B$5:$B$7,"=X")*D45 -> 36
A48: Team Concurrent | B48: # of Skeet Places | C48: # of Trap Places | D48: # of Sporting Places
A49: Novice | B49: 3 | C49: 2 | D49: 3
...

Sheet Team Setup
A1: Team ID | B1: Team Name | C1: Head Coach | D1: Email | E1: Address | F1: City | G1: State | H1: ZIP | I1: Phone | J1: Team Affiliation
A2: T001 | B2: High Plains Drifters | C2: Tim Wolfe | D2: Tim@example.com | E2: 1234 Rose Lane | F2: Bennett | G2: CO | H2: 80122 | I2: 303-999-1234 | J2: USAYESS
A3: T002 | B3: Rocky Mountain Clay Busters
A4: T003
A5: T004
A6: T005
A7: T006
A8: T007
A9: T008
A10: T009
A11: T010
A12: T011
A13: T012
A14: T013
A15: T014
... A51: T050

Sheet Individual Setup
A1: Shooter ID | B1: First Name | C1: Last Name | D1: Birthdate | E1: Sex | F1: Contact Phone # | G1: Contact Email | H1: Shooting Team | I1: Age Concurrent | J1: Skeet | K1: Trap | L1: Sporting Clays | M1: Skeet Class | N1: Trap Class | O1: Sporting Class
A2: 26-1000 | B2: Bill | C2: LName1 | D2: 40308 | E2: M | F2: 303-425-2425 | G2: Bill@example.com | H2: Brighton Clay Crushers | I2: Junior Varsity | J2: Y | K2: Y | L2: N
A3: 26-1001 | B3: Tom | C3: LName2 | E3: M | H3: Brighton Clay Crushers | I3: Junior Varsity
A4: 26-1002 | B4: Alan | C4: LName3 | E4: M | H4: Brighton Clay Crushers | I4: Junior Varsity
A5: 26-1003 | B5: Joan | C5: LName4 | E5: F | H5: Brighton Clay Crushers | I5: Novice
A6: 26-1004 | B6: Patricia | C6: LName5 | E6: F | H6: Brighton Clay Crushers | I6: Novice
A7: 26-1005 | B7: Rick | C7: LName6 | E7: M | H7: Brighton Clay Crushers | I7: Novice
A8: 26-1006 | B8: Matt | C8: LName7 | E8: M | H8: Brighton Clay Crushers | I8: Varsity
A9: 26-1007 | B9: Trey | C9: LName8 | E9: M | H9: Brighton Clay Crushers | I9: Varsity
A10: 26-1008 | B10: Christy | C10: LName9 | E10: F | H10: Forge Christian Shooting Team | I10: Intermediate
A11: 26-1009 | B11: Steve | C11: LName10 | E11: M | H11: Forge Christian Shooting Team | I11: Intermediate
A12: 26-1010 | B12: Marty | C12: LName11 | E12: M | H12: Forge Christian Shooting Team | I12: Intermediate
A13: 26-1011 | B13: Susan | C13: LName12 | E13: F | H13: Forge Christian Shooting Team | I13: Varsity
A14: 26-1012 | B14: Paul | C14: LName13 | E14: M | H14: Forge Christian Shooting Team | I14: Varsity
... A49: 26-1047 | B49: Dee | C49: LName48 | E49: F | H49: Wiggins Tigers Sporting Club | I49: Novice
A50: 26-1048
A51: 26-1049
A52: 26-1050
A53: 26-1051
A54: 26-1052
A55: 26-1053
A56: 26-1054
A57: 26-1055
A58: 26-1056
A59: 26-1057
A60: 26-1058
A61: 26-1059
... A234: 26-1232

Sheet Shooter-Squad Assignment
A1: Shooter ID | B1: Team | C1: First Name | D1: Last Name | E1: Full Name | F1: Participant Concurrent | G1: Skeet | H1: Concurrent Squad | I1: Squad Position | J1: Shooting Time | K1: Ind Skeet Squad Key | L1: Team Concurrent | M1: Skeet Squad # | N1: Shooter Key | O1: Trap | P1: Concurrent Squad | Q1: Squad Position | R1: Shooting Time | S1: Sporting Clays | T1: Concurrent Squad | U1: Squad Position | V1: Shooting Time | W1: Trap Shooter Key | X1: Trap Squad Key | Y1: Trap Squad # | Z1: Sporting Shooter Key | AA1: Sporting Squad Key | AB1: Sporting Squad #
A2: 24-1004 | B2: =INDEX('Tournament List'!$L:$L,MATCH($A2,'Tournament List'!$A:$A,0)) -> Brighton Clay Crushers | C2: =INDEX('Tournament List'!$B:$B,MATCH($A2,'Tournament List'!$A:$A,0)) -> Matt | D2: =INDEX('Tournament List'!$C:$C,MATCH($A2,'Tournament List'!$A:$A,0)) -> Last Name5 | E2: =IF(C2<>"",C2&" "&D2,"") -> Matt Last Name5 | F2: =INDEX('Tournament List'!$M:$M,MATCH($A2,'Tournament List'!$A:$A,0)) -> Varsity | G2: Skeet | K2: =IF(H2<>"",B2&"-"&H2&"-"&G2&"-Pos"&I2,"") | L2: =IF(H2<>"",IFERROR(INDEX('Tournament Setup'!$B$59:$B$78,MATCH(H2,SquadConcurrents,0)),""),"") | M2: =IFERROR(INDEX('Squad Listing'!$A:$A,MATCH(B2&"-"&H2&"-"&G2,'Squad Listing'!$B:$B,0)),"") | N2: =IF(H2<>"",I2,"") | O2: Trap | S2: Sporting Clays | W2: =IF(P2<>"",B2&"-"&P2&"-"&O2&"-Pos"&Q2,"") | X2: =IF(P2<>"",B2&"-"&P2&"-"&O2,"") | Y2: =IFERROR(INDEX('Squad Listing'!$A:$A,MATCH(X2,'Squad Listing'!$B:$B,0)),"") | Z2: =IF(T2<>"",B2&"-"&T2&"-"&S2&"-Pos"&U2,"") | AA2: =IF(T2<>"",B2&"-"&T2&"-"&S2,"") | AB2: =IFERROR(INDEX('Squad Listing'!$A:$A,MATCH(AA2,'Squad Listing'!$B:$B,0)),"")
A3: 24-1016 | B3: =INDEX('Tournament List'!$L:$L,MATCH($A3,'Tournament List'!$A:$A,0)) -> Brighton Clay Crushers | C3: =INDEX('Tournament List'!$B:$B,MATCH($A3,'Tournament List'!$A:$A,0)) -> Joan | D3: =INDEX('Tournament List'!$C:$C,MATCH($A3,'Tournament List'!$A:$A,0)) -> Last Name17 | E3: =IF(C3<>"",C3&" "&D3,"") -> Joan Last Name17 | F3: =INDEX('Tournament List'!$M:$M,MATCH($A3,'Tournament List'!$A:$A,0)) -> Novice | G3: Skeet | H3: Novice 1 | I3: 1 | J3: 9:00 | K3: =IF(H3<>"",B3&"-"&H3&"-"&G3&"-Pos"&I3,"") -> Brighton Clay Crushers-Novice 1-Skeet-Pos1 | L3: =IF(H3<>"",IFERROR(INDEX('Tournament Setup'!$B$59:$B$78,MATCH(H3,SquadConcurrents,0)),""),"") -> Novice | M3: =IFERROR(INDEX('Squad Listing'!$A:$A,MATCH(B3&"-"&H3&"-"&G3,'Squad Listing'!$B:$B,0)),"") -> 10 | N3: =IF(H3<>"",I3,"") -> 1 | O3: Trap | S3: Sporting Clays | W3: =IF(P3<>"",B3&"-"&P3&"-"&O3&"-Pos"&Q3,"") | X3: =IF(P3<>"",B3&"-"&P3&"-"&O3,"") | Y3: =IFERROR(INDEX('Squad Listing'!$A:$A,MATCH(X3,'Squad Listing'!$B:$B,0)),"") | Z3: =IF(T3<>"",B3&"-"&T3&"-"&S3&"-Pos"&U3,"") | AA3: =IF(T3<>"",B3&"-"&T3&"-"&S3,"") | AB3: =IFERROR(INDEX('Squad Listing'!$A:$A,MATCH(AA3,'Squad Listing'!$B:$B,0)),"")
A4: 24-1034 | B4: =INDEX('Tournament List'!$L:$L,MATCH($A4,'Tournament List'!$A:$A,0)) -> Brighton Clay Crushers | C4: =INDEX('Tournament List'!$B:$B,MATCH($A4,'Tournament List'!$A:$A,0)) -> Patricia | D4: =INDEX('Tournament List'!$C:$C,MATCH($A4,'Tournament List'!$A:$A,0)) -> Last Name35 | E4: =IF(C4<>"",C4&" "&D4,"") -> Patricia Last Name35 | F4: =INDEX('Tournament List'!$M:$M,MATCH($A4,'Tournament List'!$A:$A,0)) -> Novice | G4: Skeet | H4: Novice 1 | I4: 2 | J4: 9:00 | K4: =IF(H4<>"",B4&"-"&H4&"-"&G4&"-Pos"&I4,"") -> Brighton Clay Crushers-Novice 1-Skeet-Pos2 | L4: =IF(H4<>"",IFERROR(INDEX('Tournament Setup'!$B$59:$B$78,MATCH(H4,SquadConcurrents,0)),""),"") -> Novice | M4: =IFERROR(INDEX('Squad Listing'!$A:$A,MATCH(B4&"-"&H4&"-"&G4,'Squad Listing'!$B:$B,0)),"") -> 10 | N4: =IF(H4<>"",I4,"") -> 2 | O4: Trap | S4: Sporting Clays | W4: =IF(P4<>"",B4&"-"&P4&"-"&O4&"-Pos"&Q4,"") | X4: =IF(P4<>"",B4&"-"&P4&"-"&O4,"") | Y4: =IFERROR(INDEX('Squad Listing'!$A:$A,MATCH(X4,'Squad Listing'!$B:$B,0)),"") | Z4: =IF(T4<>"",B4&"-"&T4&"-"&S4&"-Pos"&U4,"") | AA4: =IF(T4<>"",B4&"-"&T4&"-"&S4,"") | AB4: =IFERROR(INDEX('Squad Listing'!$A:$A,MATCH(AA4,'Squad Listing'!$B:$B,0)),"")
A5: 24-1046 | B5: =INDEX('Tournament List'!$L:$L,MATCH($A5,'Tournament List'!$A:$A,0)) -> Brighton Clay Crushers | C5: =INDEX('Tournament List'!$B:$B,MATCH($A5,'Tournament List'!$A:$A,0)) -> Rick | D5: =INDEX('Tournament List'!$C:$C,MATCH($A5,'Tournament List'!$A:$A,0)) -> Last Name47 | E5: =IF(C5<>"",C5&" "&D5,"") -> Rick Last Name47 | F5: =INDEX('Tournament List'!$M:$M,MATCH($A5,'Tournament List'!$A:$A,0)) -> Novice | G5: Skeet | H5: Novice 1 | I5: 3 | J5: 9:00 | K5: =IF(H5<>"",B5&"-"&H5&"-"&G5&"-Pos"&I5,"") -> Brighton Clay Crushers-Novice 1-Skeet-Pos3 | L5: =IF(H5<>"",IFERROR(INDEX('Tournament Setup'!$B$59:$B$78,MATCH(H5,SquadConcurrents,0)),""),"") -> Novice | M5: =IFERROR(INDEX('Squad Listing'!$A:$A,MATCH(B5&"-"&H5&"-"&G5,'Squad Listing'!$B:$B,0)),"") -> 10 | N5: =IF(H5<>"",I5,"") -> 3 | O5: Trap | S5: Sporting Clays | W5: =IF(P5<>"",B5&"-"&P5&"-"&O5&"-Pos"&Q5,"") | X5: =IF(P5<>"",B5&"-"&P5&"-"&O5,"") | Y5: =IFERROR(INDEX('Squad Listing'!$A:$A,MATCH(X5,'Squad Listing'!$B:$B,0)),"") | Z5: =IF(T5<>"",B5&"-"&T5&"-"&S5&"-Pos"&U5,"") | AA5: =IF(T5<>"",B5&"-"&T5&"-"&S5,"") | AB5: =IFERROR(INDEX('Squad Listing'!$A:$A,MATCH(AA5,'Squad Listing'!$B:$B,0)),"")
A6: 24-1022 | B6: =INDEX('Tournament List'!$L:$L,MATCH($A6,'Tournament List'!$A:$A,0)) -> Brighton Clay Crushers | C6: =INDEX('Tournament List'!$B:$B,MATCH($A6,'Tournament List'!$A:$A,0)) -> Tom | D6: =INDEX('Tournament List'!$C:$C,MATCH($A6,'Tournament List'!$A:$A,0)) -> Last Name23 | E6: =IF(C6<>"",C6&" "&D6,"") -> Tom Last Name23 | F6: =INDEX('Tournament List'!$M:$M,MATCH($A6,'Tournament List'!$A:$A,0)) -> Junior Varsity | G6: Skeet | H6: Junior Varsity 1 | I6: 1 | K6: =IF(H6<>"",B6&"-"&H6&"-"&G6&"-Pos"&I6,"") -> Brighton Clay Crushers-Junior Varsity 1-Skeet-Pos1 | L6: =IF(H6<>"",IFERROR(INDEX('Tournament Setup'!$B$59:$B$78,MATCH(H6,SquadConcurrents,0)),""),"") -> Junior Varsity | M6: =IFERROR(INDEX('Squad Listing'!$A:$A,MATCH(B6&"-"&H6&"-"&G6,'Squad Listing'!$B:$B,0)),"") -> 7 | N6: =IF(H6<>"",I6,"") -> 1 | O6: Trap | S6: Sporting Clays | W6: =IF(P6<>"",B6&"-"&P6&"-"&O6&"-Pos"&Q6,"") | X6: =IF(P6<>"",B6&"-"&P6&"-"&O6,"") | Y6: =IFERROR(INDEX('Squad Listing'!$A:$A,MATCH(X6,'Squad Listing'!$B:$B,0)),"") | Z6: =IF(T6<>"",B6&"-"&T6&"-"&S6&"-Pos"&U6,"") | AA6: =IF(T6<>"",B6&"-"&T6&"-"&S6,"") | AB6: =IFERROR(INDEX('Squad Listing'!$A:$A,MATCH(AA6,'Squad Listing'!$B:$B,0)),"")
A7: 24-1010 | B7: =INDEX('Tournament List'!$L:$L,MATCH($A7,'Tournament List'!$A:$A,0)) -> Brighton Clay Crushers | C7: =INDEX('Tournament List'!$B:$B,MATCH($A7,'Tournament List'!$A:$A,0)) -> Bill | D7: =INDEX('Tournament List'!$C:$C,MATCH($A7,'Tournament List'!$A:$A,0)) -> Last Name11 | E7: =IF(C7<>"",C7&" "&D7,"") -> Bill Last Name11 | F7: =INDEX('Tournament List'!$M:$M,MATCH($A7,'Tournament List'!$A:$A,0)) -> Junior Varsity | G7: Skeet | H7: Junior Varsity 1 | I7: 2 | K7: =IF(H7<>"",B7&"-"&H7&"-"&G7&"-Pos"&I7,"") -> Brighton Clay Crushers-Junior Varsity 1-Skeet-Pos2 | L7: =IF(H7<>"",IFERROR(INDEX('Tournament Setup'!$B$59:$B$78,MATCH(H7,SquadConcurrents,0)),""),"") -> Junior Varsity | M7: =IFERROR(INDEX('Squad Listing'!$A:$A,MATCH(B7&"-"&H7&"-"&G7,'Squad Listing'!$B:$B,0)),"") -> 7 | N7: =IF(H7<>"",I7,"") -> 2 | O7: Trap | S7: Sporting Clays | W7: =IF(P7<>"",B7&"-"&P7&"-"&O7&"-Pos"&Q7,"") | X7: =IF(P7<>"",B7&"-"&P7&"-"&O7,"") | Y7: =IFERROR(INDEX('Squad Listing'!$A:$A,MATCH(X7,'Squad Listing'!$B:$B,0)),"") | Z7: =IF(T7<>"",B7&"-"&T7&"-"&S7&"-Pos"&U7,"") | AA7: =IF(T7<>"",B7&"-"&T7&"-"&S7,"") | AB7: =IFERROR(INDEX('Squad Listing'!$A:$A,MATCH(AA7,'Squad Listing'!$B:$B,0)),"")
A8: 24-1028 | B8: =INDEX('Tournament List'!$L:$L,MATCH($A8,'Tournament List'!$A:$A,0)) -> Brighton Clay Crushers | C8: =INDEX('Tournament List'!$B:$B,MATCH($A8,'Tournament List'!$A:$A,0)) -> Alan | D8: =INDEX('Tournament List'!$C:$C,MATCH($A8,'Tournament List'!$A:$A,0)) -> Last Name29 | E8: =IF(C8<>"",C8&" "&D8,"") -> Alan Last Name29 | F8: =INDEX('Tournament List'!$M:$M,MATCH($A8,'Tournament List'!$A:$A,0)) -> Junior Varsity | G8: Skeet | H8: Junior Varsity 1 | I8: 3 | K8: =IF(H8<>"",B8&"-"&H8&"-"&G8&"-Pos"&I8,"") -> Brighton Clay Crushers-Junior Varsity 1-Skeet-Pos3 | L8: =IF(H8<>"",IFERROR(INDEX('Tournament Setup'!$B$59:$B$78,MATCH(H8,SquadConcurrents,0)),""),"") -> Junior Varsity | M8: =IFERROR(INDEX('Squad Listing'!$A:$A,MATCH(B8&"-"&H8&"-"&G8,'Squad Listing'!$B:$B,0)),"") -> 7 | N8: =IF(H8<>"",I8,"") -> 3 | O8: Trap | S8: Sporting Clays | W8: =IF(P8<>"",B8&"-"&P8&"-"&O8&"-Pos"&Q8,"") | X8: =IF(P8<>"",B8&"-"&P8&"-"&O8,"") | Y8: =IFERROR(INDEX('Squad Listing'!$A:$A,MATCH(X8,'Squad Listing'!$B:$B,0)),"") | Z8: =IF(T8<>"",B8&"-"&T8&"-"&S8&"-Pos"&U8,"") | AA8: =IF(T8<>"",B8&"-"&T8&"-"&S8,"") | AB8: =IFERROR(INDEX('Squad Listing'!$A:$A,MATCH(AA8,'Squad Listing'!$B:$B,0)),"")
A9: 24-1040 | B9: =INDEX('Tournament List'!$L:$L,MATCH($A9,'Tournament List'!$A:$A,0)) -> Brighton Clay Crushers | C9: =INDEX('Tournament List'!$B:$B,MATCH($A9,'Tournament List'!$A:$A,0)) -> Trey | D9: =INDEX('Tournament List'!$C:$C,MATCH($A9,'Tournament List'!$A:$A,0)) -> Last Name41 | E9: =IF(C9<>"",C9&" "&D9,"") -> Trey Last Name41 | F9: =INDEX('Tournament List'!$M:$M,MATCH($A9,'Tournament List'!$A:$A,0)) -> Varsity | G9: Skeet | K9: =IF(H9<>"",B9&"-"&H9&"-"&G9&"-Pos"&I9,"") | L9: =IF(H9<>"",IFERROR(INDEX('Tournament Setup'!$B$59:$B$78,MATCH(H9,SquadConcurrents,0)),""),"") | M9: =IFERROR(INDEX('Squad Listing'!$A:$A,MATCH(B9&"-"&H9&"-"&G9,'Squad Listing'!$B:$B,0)),"") | N9: =IF(H9<>"",I9,"") | O9: Trap | S9: Sporting Clays | W9: =IF(P9<>"",B9&"-"&P9&"-"&O9&"-Pos"&Q9,"") | X9: =IF(P9<>"",B9&"-"&P9&"-"&O9,"") | Y9: =IFERROR(INDEX('Squad Listing'!$A:$A,MATCH(X9,'Squad Listing'!$B:$B,0)),"") | Z9: =IF(T9<>"",B9&"-"&T9&"-"&S9&"-Pos"&U9,"") | AA9: =IF(T9<>"",B9&"-"&T9&"-"&S9,"") | AB9: =IFERROR(INDEX('Squad Listing'!$A:$A,MATCH(AA9,'Squad Listing'!$B:$B,0)),"")
A10: 24-1009 | B10: =INDEX('Tournament List'!$L:$L,MATCH($A10,'Tournament List'!$A:$A,0)) -> Forge Christian Shooting Team | C10: =INDEX('Tournament List'!$B:$B,MATCH($A10,'Tournament List'!$A:$A,0)) -> Christy | D10: =INDEX('Tournament List'!$C:$C,MATCH($A10,'Tournament List'!$A:$A,0)) -> Last Name10 | E10: =IF(C10<>"",C10&" "&D10,"") -> Christy Last Name10 | F10: =INDEX('Tournament List'!$M:$M,MATCH($A10,'Tournament List'!$A:$A,0)) -> Intermediate | G10: Skeet | H10: Intermediate 1 | I10: 1 | K10: =IF(H10<>"",B10&"-"&H10&"-"&G10&"-Pos"&I10,"") -> Forge Christian Shooting Team-Intermediate 1-Skeet-Pos1 | L10: =IF(H10<>"",IFERROR(INDEX('Tournament Setup'!$B$59:$B$78,MATCH(H10,SquadConcurrents,0)),""),"") -> Intermediate | M10: =IFERROR(INDEX('Squad Listing'!$A:$A,MATCH(B10&"-"&H10&"-"&G10,'Squad Listing'!$B:$B,0)),"") -> 61 | N10: =IF(H10<>"",I10,"") -> 1 | O10: Trap | S10: Sporting Clays | W10: =IF(P10<>"",B10&"-"&P10&"-"&O10&"-Pos"&Q10,"") | X10: =IF(P10<>"",B10&"-"&P10&"-"&O10,"") | Y10: =IFERROR(INDEX('Squad Listing'!$A:$A,MATCH(X10,'Squad Listing'!$B:$B,0)),"") | Z10: =IF(T10<>"",B10&"-"&T10&"-"&S10&"-Pos"&U10,"") | AA10: =IF(T10<>"",B10&"-"&T10&"-"&S10,"") | AB10: =IFERROR(INDEX('Squad Listing'!$A:$A,MATCH(AA10,'Squad Listing'!$B:$B,0)),"")
A11: 24-1021 | B11: =INDEX('Tournament List'!$L:$L,MATCH($A11,'Tournament List'!$A:$A,0)) -> Forge Christian Shooting Team | C11: =INDEX('Tournament List'!$B:$B,MATCH($A11,'Tournament List'!$A:$A,0)) -> Steve | D11: =INDEX('Tournament List'!$C:$C,MATCH($A11,'Tournament List'!$A:$A,0)) -> Last Name22 | E11: =IF(C11<>"",C11&" "&D11,"") -> Steve Last Name22 | F11: =INDEX('Tournament List'!$M:$M,MATCH($A11,'Tournament List'!$A:$A,0)) -> Intermediate | G11: Skeet | H11: Intermediate 1 | I11: 2 | K11: =IF(H11<>"",B11&"-"&H11&"-"&G11&"-Pos"&I11,"") -> Forge Christian Shooting Team-Intermediate 1-Skeet-Pos2 | L11: =IF(H11<>"",IFERROR(INDEX('Tournament Setup'!$B$59:$B$78,MATCH(H11,SquadConcurrents,0)),""),"") -> Intermediate | M11: =IFERROR(INDEX('Squad Listing'!$A:$A,MATCH(B11&"-"&H11&"-"&G11,'Squad Listing'!$B:$B,0)),"") -> 61 | N11: =IF(H11<>"",I11,"") -> 2 | O11: Trap | S11: Sporting Clays | W11: =IF(P11<>"",B11&"-"&P11&"-"&O11&"-Pos"&Q11,"") | X11: =IF(P11<>"",B11&"-"&P11&"-"&O11,"") | Y11: =IFERROR(INDEX('Squad Listing'!$A:$A,MATCH(X11,'Squad Listing'!$B:$B,0)),"") | Z11: =IF(T11<>"",B11&"-"&T11&"-"&S11&"-Pos"&U11,"") | AA11: =IF(T11<>"",B11&"-"&T11&"-"&S11,"") | AB11: =IFERROR(INDEX('Squad Listing'!$A:$A,MATCH(AA11,'Squad Listing'!$B:$B,0)),"")
A12: 24-1033 | B12: =INDEX('Tournament List'!$L:$L,MATCH($A12,'Tournament List'!$A:$A,0)) -> Forge Christian Shooting Team | C12: =INDEX('Tournament List'!$B:$B,MATCH($A12,'Tournament List'!$A:$A,0)) -> Marty | D12: =INDEX('Tournament List'!$C:$C,MATCH($A12,'Tournament List'!$A:$A,0)) -> Last Name34 | E12: =IF(C12<>"",C12&" "&D12,"") -> Marty Last Name34 | F12: =INDEX('Tournament List'!$M:$M,MATCH($A12,'Tournament List'!$A:$A,0)) -> Intermediate | G12: Skeet | H12: Intermediate 1 | I12: 3 | K12: =IF(H12<>"",B12&"-"&H12&"-"&G12&"-Pos"&I12,"") -> Forge Christian Shooting Team-Intermediate 1-Skeet-Pos3 | L12: =IF(H12<>"",IFERROR(INDEX('Tournament Setup'!$B$59:$B$78,MATCH(H12,SquadConcurrents,0)),""),"") -> Intermediate | M12: =IFERROR(INDEX('Squad Listing'!$A:$A,MATCH(B12&"-"&H12&"-"&G12,'Squad Listing'!$B:$B,0)),"") -> 61 | N12: =IF(H12<>"",I12,"") -> 3 | O12: Trap | S12: Sporting Clays | W12: =IF(P12<>"",B12&"-"&P12&"-"&O12&"-Pos"&Q12,"") | X12: =IF(P12<>"",B12&"-"&P12&"-"&O12,"") | Y12: =IFERROR(INDEX('Squad Listing'!$A:$A,MATCH(X12,'Squad Listing'!$B:$B,0)),"") | Z12: =IF(T12<>"",B12&"-"&T12&"-"&S12&"-Pos"&U12,"") | AA12: =IF(T12<>"",B12&"-"&T12&"-"&S12,"") | AB12: =IFERROR(INDEX('Squad Listing'!$A:$A,MATCH(AA12,'Squad Listing'!$B:$B,0)),"")
A13: 24-1045 | B13: =INDEX('Tournament List'!$L:$L,MATCH($A13,'Tournament List'!$A:$A,0)) -> Forge Christian Shooting Team | C13: =INDEX('Tournament List'!$B:$B,MATCH($A13,'Tournament List'!$A:$A,0)) -> Sam | D13: =INDEX('Tournament List'!$C:$C,MATCH($A13,'Tournament List'!$A:$A,0)) -> Last Name46 | E13: =IF(C13<>"",C13&" "&D13,"") -> Sam Last Name46 | F13: =INDEX('Tournament List'!$M:$M,MATCH($A13,'Tournament List'!$A:$A,0)) -> Varsity | G13: Skeet | H13: Varsity 1 | I13: 1 | K13: =IF(H13<>"",B13&"-"&H13&"-"&G13&"-Pos"&I13,"") -> Forge Christian Shooting Team-Varsity 1-Skeet-Pos1 | L13: =IF(H13<>"",IFERROR(INDEX('Tournament Setup'!$B$59:$B$78,MATCH(H13,SquadConcurrents,0)),""),"") -> Varsity | M13: =IFERROR(INDEX('Squad Listing'!$A:$A,MATCH(B13&"-"&H13&"-"&G13,'Squad Listing'!$B:$B,0)),"") -> 74 | N13: =IF(H13<>"",I13,"") -> 1 | O13: Trap | S13: Sporting Clays | W13: =IF(P13<>"",B13&"-"&P13&"-"&O13&"-Pos"&Q13,"") | X13: =IF(P13<>"",B13&"-"&P13&"-"&O13,"") | Y13: =IFERROR(INDEX('Squad Listing'!$A:$A,MATCH(X13,'Squad Listing'!$B:$B,0)),"") | Z13: =IF(T13<>"",B13&"-"&T13&"-"&S13&"-Pos"&U13,"") | AA13: =IF(T13<>"",B13&"-"&T13&"-"&S13,"") | AB13: =IFERROR(INDEX('Squad Listing'!$A:$A,MATCH(AA13,'Squad Listing'!$B:$B,0)),"")
A14: 24-1015 | B14: =INDEX('Tournament List'!$L:$L,MATCH($A14,'Tournament List'!$A:$A,0)) -> Forge Christian Shooting Team | C14: =INDEX('Tournament List'!$B:$B,MATCH($A14,'Tournament List'!$A:$A,0)) -> Paul | D14: =INDEX('Tournament List'!$C:$C,MATCH($A14,'Tournament List'!$A:$A,0)) -> Last Name16 | E14: =IF(C14<>"",C14&" "&D14,"") -> Paul Last Name16 | F14: =INDEX('Tournament List'!$M:$M,MATCH($A14,'Tournament List'!$A:$A,0)) -> Varsity | G14: Skeet | K14: =IF(H14<>"",B14&"-"&H14&"-"&G14&"-Pos"&I14,"") | L14: =IF(H14<>"",IFERROR(INDEX('Tournament Setup'!$B$59:$B$78,MATCH(H14,SquadConcurrents,0)),""),"") | M14: =IFERROR(INDEX('Squad Listing'!$A:$A,MATCH(B14&"-"&H14&"-"&G14,'Squad Listing'!$B:$B,0)),"") | N14: =IF(H14<>"",I14,"") | O14: Trap | S14: Sporting Clays | W14: =IF(P14<>"",B14&"-"&P14&"-"&O14&"-Pos"&Q14,"") | X14: =IF(P14<>"",B14&"-"&P14&"-"&O14,"") | Y14: =IFERROR(INDEX('Squad Listing'!$A:$A,MATCH(X14,'Squad Listing'!$B:$B,0)),"") | Z14: =IF(T14<>"",B14&"-"&T14&"-"&S14&"-Pos"&U14,"") | AA14: =IF(T14<>"",B14&"-"&T14&"-"&S14,"") | AB14: =IFERROR(INDEX('Squad Listing'!$A:$A,MATCH(AA14,'Squad Listing'!$B:$B,0)),"")
A15: 24-1027 | B15: =INDEX('Tournament List'!$L:$L,MATCH($A15,'Tournament List'!$A:$A,0)) -> Forge Christian Shooting Team | C15: =INDEX('Tournament List'!$B:$B,MATCH($A15,'Tournament List'!$A:$A,0)) -> Brad | D15: =INDEX('Tournament List'!$C:$C,MATCH($A15,'Tournament List'!$A:$A,0)) -> Last Name28 | E15: =IF(C15<>"",C15&" "&D15,"") -> Brad Last Name28 | F15: =INDEX('Tournament List'!$M:$M,MATCH($A15,'Tournament List'!$A:$A,0)) -> Varsity | G15: Skeet | H15: Varsity 1 | I15: 2 | K15: =IF(H15<>"",B15&"-"&H15&"-"&G15&"-Pos"&I15,"") -> Forge Christian Shooting Team-Varsity 1-Skeet-Pos2 | L15: =IF(H15<>"",IFERROR(INDEX('Tournament Setup'!$B$59:$B$78,MATCH(H15,SquadConcurrents,0)),""),"") -> Varsity | M15: =IFERROR(INDEX('Squad Listing'!$A:$A,MATCH(B15&"-"&H15&"-"&G15,'Squad Listing'!$B:$B,0)),"") -> 74 | N15: =IF(H15<>"",I15,"") -> 2 | O15: Trap | S15: Sporting Clays | W15: =IF(P15<>"",B15&"-"&P15&"-"&O15&"-Pos"&Q15,"") | X15: =IF(P15<>"",B15&"-"&P15&"-"&O15,"") | Y15: =IFERROR(INDEX('Squad Listing'!$A:$A,MATCH(X15,'Squad Listing'!$B:$B,0)),"") | Z15: =IF(T15<>"",B15&"-"&T15&"-"&S15&"-Pos"&U15,"") | AA15: =IF(T15<>"",B15&"-"&T15&"-"&S15,"") | AB15: =IFERROR(INDEX('Squad Listing'!$A:$A,MATCH(AA15,'Squad Listing'!$B:$B,0)),"")
A16: 24-1039 | B16: =INDEX('Tournament List'!$L:$L,MATCH($A16,'Tournament List'!$A:$A,0)) -> Forge Christian Shooting Team | C16: =INDEX('Tournament List'!$B:$B,MATCH($A16,'Tournament List'!$A:$A,0)) -> Troy | D16: =INDEX('Tournament List'!$C:$C,MATCH($A16,'Tournament List'!$A:$A,0)) -> Last Name40 | E16: =IF(C16<>"",C16&" "&D16,"") -> Troy Last Name40 | F16: =INDEX('Tournament List'!$M:$M,MATCH($A16,'Tournament List'!$A:$A,0)) -> Varsity | G16: Skeet | H16: Varsity 1 | I16: 3 | K16: =IF(H16<>"",B16&"-"&H16&"-"&G16&"-Pos"&I16,"") -> Forge Christian Shooting Team-Varsity 1-Skeet-Pos3 | L16: =IF(H16<>"",IFERROR(INDEX('Tournament Setup'!$B$59:$B$78,MATCH(H16,SquadConcurrents,0)),""),"") -> Varsity | M16: =IFERROR(INDEX('Squad Listing'!$A:$A,MATCH(B16&"-"&H16&"-"&G16,'Squad Listing'!$B:$B,0)),"") -> 74 | N16: =IF(H16<>"",I16,"") -> 3 | O16: Trap | S16: Sporting Clays | W16: =IF(P16<>"",B16&"-"&P16&"-"&O16&"-Pos"&Q16,"") | X16: =IF(P16<>"",B16&"-"&P16&"-"&O16,"") | Y16: =IFERROR(INDEX('Squad Listing'!$A:$A,MATCH(X16,'Squad Listing'!$B:$B,0)),"") | Z16: =IF(T16<>"",B16&"-"&T16&"-"&S16&"-Pos"&U16,"") | AA16: =IF(T16<>"",B16&"-"&T16&"-"&S16,"") | AB16: =IFERROR(INDEX('Squad Listing'!$A:$A,MATCH(AA16,'Squad Listing'!$B:$B,0)),"")
A17: 24-1003 | B17: =INDEX('Tournament List'!$L:$L,MATCH($A17,'Tournament List'!$A:$A,0)) -> Forge Christian Shooting Team | C17: =INDEX('Tournament List'!$B:$B,MATCH($A17,'Tournament List'!$A:$A,0)) -> Susan | D17: =INDEX('Tournament List'!$C:$C,MATCH($A17,'Tournament List'!$A:$A,0)) -> Last Name4 | E17: =IF(C17<>"",C17&" "&D17,"") -> Susan Last Name4 | F17: =INDEX('Tournament List'!$M:$M,MATCH($A17,'Tournament List'!$A:$A,0)) -> Varsity | G17: Skeet | K17: =IF(H17<>"",B17&"-"&H17&"-"&G17&"-Pos"&I17,"") | L17: =IF(H17<>"",IFERROR(INDEX('Tournament Setup'!$B$59:$B$78,MATCH(H17,SquadConcurrents,0)),""),"") | M17: =IFERROR(INDEX('Squad Listing'!$A:$A,MATCH(B17&"-"&H17&"-"&G17,'Squad Listing'!$B:$B,0)),"") | N17: =IF(H17<>"",I17,"") | O17: Trap | S17: Sporting Clays | W17: =IF(P17<>"",B17&"-"&P17&"-"&O17&"-Pos"&Q17,"") | X17: =IF(P17<>"",B17&"-"&P17&"-"&O17,"") | Y17: =IFERROR(INDEX('Squad Listing'!$A:$A,MATCH(X17,'Squad Listing'!$B:$B,0)),"") | Z17: =IF(T17<>"",B17&"-"&T17&"-"&S17&"-Pos"&U17,"") | AA17: =IF(T17<>"",B17&"-"&T17&"-"&S17,"") | AB17: =IFERROR(INDEX('Squad Listing'!$A:$A,MATCH(AA17,'Squad Listing'!$B:$B,0)),"")
A18: 24-1006 | B18: =INDEX('Tournament List'!$L:$L,MATCH($A18,'Tournament List'!$A:$A,0)) -> High Plains Drifters | C18: =INDEX('Tournament List'!$B:$B,MATCH($A18,'Tournament List'!$A:$A,0)) -> Blake | D18: =INDEX('Tournament List'!$C:$C,MATCH($A18,'Tournament List'!$A:$A,0)) -> Last Name7 | E18: =IF(C18<>"",C18&" "&D18,"") -> Blake Last Name7 | F18: =INDEX('Tournament List'!$M:$M,MATCH($A18,'Tournament List'!$A:$A,0)) -> Intermediate | G18: Skeet | H18: Intermediate 1 | I18: 1 | J18: 9:00 | K18: =IF(H18<>"",B18&"-"&H18&"-"&G18&"-Pos"&I18,"") -> High Plains Drifters-Intermediate 1-Skeet-Pos1 | L18: =IF(H18<>"",IFERROR(INDEX('Tournament Setup'!$B$59:$B$78,MATCH(H18,SquadConcurrents,0)),""),"") -> Intermediate | M18: =IFERROR(INDEX('Squad Listing'!$A:$A,MATCH(B18&"-"&H18&"-"&G18,'Squad Listing'!$B:$B,0)),"") -> 118 | N18: =IF(H18<>"",I18,"") -> 1 | O18: Trap | P18: Open 1 | Q18: 4 | R18: 11:00 | S18: Sporting Clays | W18: =IF(P18<>"",B18&"-"&P18&"-"&O18&"-Pos"&Q18,"") -> High Plains Drifters-Open 1-Trap-Pos4 | X18: =IF(P18<>"",B18&"-"&P18&"-"&O18,"") -> High Plains Drifters-Open 1-Trap | Y18: =IFERROR(INDEX('Squad Listing'!$A:$A,MATCH(X18,'Squad Listing'!$B:$B,0)),"") -> 165 | Z18: =IF(T18<>"",B18&"-"&T18&"-"&S18&"-Pos"&U18,"") | AA18: =IF(T18<>"",B18&"-"&T18&"-"&S18,"") | AB18: =IFERROR(INDEX('Squad Listing'!$A:$A,MATCH(AA18,'Squad Listing'!$B:$B,0)),"")
A19: 24-1030 | B19: =INDEX('Tournament List'!$L:$L,MATCH($A19,'Tournament List'!$A:$A,0)) -> High Plains Drifters | C19: =INDEX('Tournament List'!$B:$B,MATCH($A19,'Tournament List'!$A:$A,0)) -> Shelly | D19: =INDEX('Tournament List'!$C:$C,MATCH($A19,'Tournament List'!$A:$A,0)) -> Last Name31 | E19: =IF(C19<>"",C19&" "&D19,"") -> Shelly Last Name31 | F19: =INDEX('Tournament List'!$M:$M,MATCH($A19,'Tournament List'!$A:$A,0)) -> Intermediate | G19: Skeet | H19: Intermediate 1 | I19: 2 | J19: 9:00 | K19: =IF(H19<>"",B19&"-"&H19&"-"&G19&"-Pos"&I19,"") -> High Plains Drifters-Intermediate 1-Skeet-Pos2 | L19: =IF(H19<>"",IFERROR(INDEX('Tournament Setup'!$B$59:$B$78,MATCH(H19,SquadConcurrents,0)),""),"") -> Intermediate | M19: =IFERROR(INDEX('Squad Listing'!$A:$A,MATCH(B19&"-"&H19&"-"&G19,'Squad Listing'!$B:$B,0)),"") -> 118 | N19: =IF(H19<>"",I19,"") -> 2 | O19: Trap | P19: Open 1 | Q19: 5 | R19: 11:00 | S19: Sporting Clays | W19: =IF(P19<>"",B19&"-"&P19&"-"&O19&"-Pos"&Q19,"") -> High Plains Drifters-Open 1-Trap-Pos5 | X19: =IF(P19<>"",B19&"-"&P19&"-"&O19,"") -> High Plains Drifters-Open 1-Trap | Y19: =IFERROR(INDEX('Squad Listing'!$A:$A,MATCH(X19,'Squad Listing'!$B:$B,0)),"") -> 165 | Z19: =IF(T19<>"",B19&"-"&T19&"-"&S19&"-Pos"&U19,"") | AA19: =IF(T19<>"",B19&"-"&T19&"-"&S19,"") | AB19: =IFERROR(INDEX('Squad Listing'!$A:$A,MATCH(AA19,'Squad Listing'!$B:$B,0)),"")
A20: 24-1042 | B20: =INDEX('Tournament List'!$L:$L,MATCH($A20,'Tournament List'!$A:$A,0)) -> High Plains Drifters | C20: =INDEX('Tournament List'!$B:$B,MATCH($A20,'Tournament List'!$A:$A,0)) -> Terry | D20: =INDEX('Tournament List'!$C:$C,MATCH($A20,'Tournament List'!$A:$A,0)) -> Last Name43 | E20: =IF(C20<>"",C20&" "&D20,"") -> Terry Last Name43 | F20: =INDEX('Tournament List'!$M:$M,MATCH($A20,'Tournament List'!$A:$A,0)) -> Intermediate | G20: Skeet | H20: Intermediate 1 | I20: 3 | J20: 9:00 | K20: =IF(H20<>"",B20&"-"&H20&"-"&G20&"-Pos"&I20,"") -> High Plains Drifters-Intermediate 1-Skeet-Pos3 | L20: =IF(H20<>"",IFERROR(INDEX('Tournament Setup'!$B$59:$B$78,MATCH(H20,SquadConcurrents,0)),""),"") -> Intermediate | M20: =IFERROR(INDEX('Squad Listing'!$A:$A,MATCH(B20&"-"&H20&"-"&G20,'Squad Listing'!$B:$B,0)),"") -> 118 | N20: =IF(H20<>"",I20,"") -> 3 | O20: Trap | S20: Sporting Clays | T20: Open 1 | U20: 1 | W20: =IF(P20<>"",B20&"-"&P20&"-"&O20&"-Pos"&Q20,"") | X20: =IF(P20<>"",B20&"-"&P20&"-"&O20,"") | Y20: =IFERROR(INDEX('Squad Listing'!$A:$A,MATCH(X20,'Squad Listing'!$B:$B,0)),"") | Z20: =IF(T20<>"",B20&"-"&T20&"-"&S20&"-Pos"&U20,"") -> High Plains Drifters-Open 1-Sporting Clays-Pos1 | AA20: =IF(T20<>"",B20&"-"&T20&"-"&S20,"") -> High Plains Drifters-Open 1-Sporting Clays | AB20: =IFERROR(INDEX('Squad Listing'!$A:$A,MATCH(AA20,'Squad Listing'!$B:$B,0)),"") -> 146
A21: 24-1012 | B21: =INDEX('Tournament List'!$L:$L,MATCH($A21,'Tournament List'!$A:$A,0)) -> High Plains Drifters | C21: =INDEX('Tournament List'!$B:$B,MATCH($A21,'Tournament List'!$A:$A,0)) -> Bruce | D21: =INDEX('Tournament List'!$C:$C,MATCH($A21,'Tournament List'!$A:$A,0)) -> Last Name13 | E21: =IF(C21<>"",C21&" "&D21,"") -> Bruce Last Name13 | F21: =INDEX('Tournament List'!$M:$M,MATCH($A21,'Tournament List'!$A:$A,0)) -> Junior Varsity | G21: Skeet | K21: =IF(H21<>"",B21&"-"&H21&"-"&G21&"-Pos"&I21,"") | L21: =IF(H21<>"",IFERROR(INDEX('Tournament Setup'!$B$59:$B$78,MATCH(H21,SquadConcurrents,0)),""),"") | M21: =IFERROR(INDEX('Squad Listing'!$A:$A,MATCH(B21&"-"&H21&"-"&G21,'Squad Listing'!$B:$B,0)),"") | N21: =IF(H21<>"",I21,"") | O21: Trap | S21: Sporting Clays | T21: Open 1 | U21: 2 | W21: =IF(P21<>"",B21&"-"&P21&"-"&O21&"-Pos"&Q21,"") | X21: =IF(P21<>"",B21&"-"&P21&"-"&O21,"") | Y21: =IFERROR(INDEX('Squad Listing'!$A:$A,MATCH(X21,'Squad Listing'!$B:$B,0)),"") | Z21: =IF(T21<>"",B21&"-"&T21&"-"&S21&"-Pos"&U21,"") -> High Plains Drifters-Open 1-Sporting Clays-Pos2 | AA21: =IF(T21<>"",B21&"-"&T21&"-"&S21,"") -> High Plains Drifters-Open 1-Sporting Clays | AB21: =IFERROR(INDEX('Squad Listing'!$A:$A,MATCH(AA21,'Squad Listing'!$B:$B,0)),"") -> 146
A22: 24-1000 | B22: =INDEX('Tournament List'!$L:$L,MATCH($A22,'Tournament List'!$A:$A,0)) -> High Plains Drifters | C22: =INDEX('Tournament List'!$B:$B,MATCH($A22,'Tournament List'!$A:$A,0)) -> Jason | D22: =INDEX('Tournament List'!$C:$C,MATCH($A22,'Tournament List'!$A:$A,0)) -> Last Name1 | E22: =IF(C22<>"",C22&" "&D22,"") -> Jason Last Name1 | F22: =INDEX('Tournament List'!$M:$M,MATCH($A22,'Tournament List'!$A:$A,0)) -> Novice | G22: Skeet | K22: =IF(H22<>"",B22&"-"&H22&"-"&G22&"-Pos"&I22,"") | L22: =IF(H22<>"",IFERROR(INDEX('Tournament Setup'!$B$59:$B$78,MATCH(H22,SquadConcurrents,0)),""),"") | M22: =IFERROR(INDEX('Squad Listing'!$A:$A,MATCH(B22&"-"&H22&"-"&G22,'Squad Listing'!$B:$B,0)),"") | N22: =IF(H22<>"",I22,"") | O22: Trap | S22: Sporting Clays | T22: Open 1 | U22: 3 | W22: =IF(P22<>"",B22&"-"&P22&"-"&O22&"-Pos"&Q22,"") | X22: =IF(P22<>"",B22&"-"&P22&"-"&O22,"") | Y22: =IFERROR(INDEX('Squad Listing'!$A:$A,MATCH(X22,'Squad Listing'!$B:$B,0)),"") | Z22: =IF(T22<>"",B22&"-"&T22&"-"&S22&"-Pos"&U22,"") -> High Plains Drifters-Open 1-Sporting Clays-Pos3 | AA22: =IF(T22<>"",B22&"-"&T22&"-"&S22,"") -> High Plains Drifters-Open 1-Sporting Clays | AB22: =IFERROR(INDEX('Squad Listing'!$A:$A,MATCH(AA22,'Squad Listing'!$B:$B,0)),"") -> 146
A23: 24-1018 | B23: =INDEX('Tournament List'!$L:$L,MATCH($A23,'Tournament List'!$A:$A,0)) -> High Plains Drifters | C23: =INDEX('Tournament List'!$B:$B,MATCH($A23,'Tournament List'!$A:$A,0)) -> Jack | D23: =INDEX('Tournament List'!$C:$C,MATCH($A23,'Tournament List'!$A:$A,0)) -> Last Name19 | E23: =IF(C23<>"",C23&" "&D23,"") -> Jack Last Name19 | F23: =INDEX('Tournament List'!$M:$M,MATCH($A23,'Tournament List'!$A:$A,0)) -> Varsity | G23: Skeet | H23: Open 1 | I23: 1 | J23: 9:00 | K23: =IF(H23<>"",B23&"-"&H23&"-"&G23&"-Pos"&I23,"") -> High Plains Drifters-Open 1-Skeet-Pos1 | L23: =IF(H23<>"",IFERROR(INDEX('Tournament Setup'!$B$59:$B$78,MATCH(H23,SquadConcurrents,0)),""),"") -> Open | M23: =IFERROR(INDEX('Squad Listing'!$A:$A,MATCH(B23&"-"&H23&"-"&G23,'Squad Listing'!$B:$B,0)),"") -> 127 | N23: =IF(H23<>"",I23,"") -> 1 | O23: Trap | P23: Open 1 | Q23: 1 | R23: 11:00 | S23: Sporting Clays | T23: Varsity 1 | U23: 2 | W23: =IF(P23<>"",B23&"-"&P23&"-"&O23&"-Pos"&Q23,"") -> High Plains Drifters-Open 1-Trap-Pos1 | X23: =IF(P23<>"",B23&"-"&P23&"-"&O23,"") -> High Plains Drifters-Open 1-Trap | Y23: =IFERROR(INDEX('Squad Listing'!$A:$A,MATCH(X23,'Squad Listing'!$B:$B,0)),"") -> 165 | Z23: =IF(T23<>"",B23&"-"&T23&"-"&S23&"-Pos"&U23,"") -> High Plains Drifters-Varsity 1-Sporting Clays-Pos2 | AA23: =IF(T23<>"",B23&"-"&T23&"-"&S23,"") -> High Plains Drifters-Varsity 1-Sporting Clays | AB23: =IFERROR(INDEX('Squad Listing'!$A:$A,MATCH(AA23,'Squad Listing'!$B:$B,0)),"") -> 150
A24: 24-1024 | B24: =INDEX('Tournament List'!$L:$L,MATCH($A24,'Tournament List'!$A:$A,0)) -> High Plains Drifters | C24: =INDEX('Tournament List'!$B:$B,MATCH($A24,'Tournament List'!$A:$A,0)) -> Harry | D24: =INDEX('Tournament List'!$C:$C,MATCH($A24,'Tournament List'!$A:$A,0)) -> Last Name25 | E24: =IF(C24<>"",C24&" "&D24,"") -> Harry Last Name25 | F24: =INDEX('Tournament List'!$M:$M,MATCH($A24,'Tournament List'!$A:$A,0)) -> Varsity | G24: Skeet | H24: Open 1 | I24: 2 | J24: 9:00 | K24: =IF(H24<>"",B24&"-"&H24&"-"&G24&"-Pos"&I24,"") -> High Plains Drifters-Open 1-Skeet-Pos2 | L24: =IF(H24<>"",IFERROR(INDEX('Tournament Setup'!$B$59:$B$78,MATCH(H24,SquadConcurrents,0)),""),"") -> Open | M24: =IFERROR(INDEX('Squad Listing'!$A:$A,MATCH(B24&"-"&H24&"-"&G24,'Squad Listing'!$B:$B,0)),"") -> 127 | N24: =IF(H24<>"",I24,"") -> 2 | O24: Trap | P24: Open 1 | Q24: 2 | R24: 11:00 | S24: Sporting Clays | T24: Varsity 1 | U24: 1 | W24: =IF(P24<>"",B24&"-"&P24&"-"&O24&"-Pos"&Q24,"") -> High Plains Drifters-Open 1-Trap-Pos2 | X24: =IF(P24<>"",B24&"-"&P24&"-"&O24,"") -> High Plains Drifters-Open 1-Trap | Y24: =IFERROR(INDEX('Squad Listing'!$A:$A,MATCH(X24,'Squad Listing'!$B:$B,0)),"") -> 165 | Z24: =IF(T24<>"",B24&"-"&T24&"-"&S24&"-Pos"&U24,"") -> High Plains Drifters-Varsity 1-Sporting Clays-Pos1 | AA24: =IF(T24<>"",B24&"-"&T24&"-"&S24,"") -> High Plains Drifters-Varsity 1-Sporting Clays | AB24: =IFERROR(INDEX('Squad Listing'!$A:$A,MATCH(AA24,'Squad Listing'!$B:$B,0)),"") -> 150
A25: 24-1036 | B25: =INDEX('Tournament List'!$L:$L,MATCH($A25,'Tournament List'!$A:$A,0)) -> High Plains Drifters | C25: =INDEX('Tournament List'!$B:$B,MATCH($A25,'Tournament List'!$A:$A,0)) -> Will | D25: =INDEX('Tournament List'!$C:$C,MATCH($A25,'Tournament List'!$A:$A,0)) -> Last Name37 | E25: =IF(C25<>"",C25&" "&D25,"") -> Will Last Name37 | F25: =INDEX('Tournament List'!$M:$M,MATCH($A25,'Tournament List'!$A:$A,0)) -> Varsity | G25: Skeet | H25: Open 1 | I25: 3 | J25: 9:00 | K25: =IF(H25<>"",B25&"-"&H25&"-"&G25&"-Pos"&I25,"") -> High Plains Drifters-Open 1-Skeet-Pos3 | L25: =IF(H25<>"",IFERROR(INDEX('Tournament Setup'!$B$59:$B$78,MATCH(H25,SquadConcurrents,0)),""),"") -> Open | M25: =IFERROR(INDEX('Squad Listing'!$A:$A,MATCH(B25&"-"&H25&"-"&G25,'Squad Listing'!$B:$B,0)),"") -> 127 | N25: =IF(H25<>"",I25,"") -> 3 | O25: Trap | P25: Open 1 | Q25: 3 | R25: 11:00 | S25: Sporting Clays | T25: Varsity 1 | U25: 3 | W25: =IF(P25<>"",B25&"-"&P25&"-"&O25&"-Pos"&Q25,"") -> High Plains Drifters-Open 1-Trap-Pos3 | X25: =IF(P25<>"",B25&"-"&P25&"-"&O25,"") -> High Plains Drifters-Open 1-Trap | Y25: =IFERROR(INDEX('Squad Listing'!$A:$A,MATCH(X25,'Squad Listing'!$B:$B,0)),"") -> 165 | Z25: =IF(T25<>"",B25&"-"&T25&"-"&S25&"-Pos"&U25,"") -> High Plains Drifters-Varsity 1-Sporting Clays-Pos3 | AA25: =IF(T25<>"",B25&"-"&T25&"-"&S25,"") -> High Plains Drifters-Varsity 1-Sporting Clays | AB25: =IFERROR(INDEX('Squad Listing'!$A:$A,MATCH(AA25,'Squad Listing'!$B:$B,0)),"") -> 150
A26: 24-1011 | B26: =INDEX('Tournament List'!$L:$L,MATCH($A26,'Tournament List'!$A:$A,0)) -> Littleton Target Masters | C26: =INDEX('Tournament List'!$B:$B,MATCH($A26,'Tournament List'!$A:$A,0)) -> Bob | D26: =INDEX('Tournament List'!$C:$C,MATCH($A26,'Tournament List'!$A:$A,0)) -> Last Name12 | E26: =IF(C26<>"",C26&" "&D26,"") -> Bob Last Name12 | F26: =INDEX('Tournament List'!$M:$M,MATCH($A26,'Tournament List'!$A:$A,0)) -> Collegiate | G26: Skeet | H26: Collegiate 1 | I26: 1 | K26: =IF(H26<>"",B26&"-"&H26&"-"&G26&"-Pos"&I26,"") -> Littleton Target Masters-Collegiate 1-Skeet-Pos1 | L26: =IF(H26<>"",IFERROR(INDEX('Tournament Setup'!$B$59:$B$78,MATCH(H26,SquadConcurrents,0)),""),"") -> Collegiate | M26: =IFERROR(INDEX('Squad Listing'!$A:$A,MATCH(B26&"-"&H26&"-"&G26,'Squad Listing'!$B:$B,0)),"") -> 172 | N26: =IF(H26<>"",I26,"") -> 1 | O26: Trap | S26: Sporting Clays | W26: =IF(P26<>"",B26&"-"&P26&"-"&O26&"-Pos"&Q26,"") | X26: =IF(P26<>"",B26&"-"&P26&"-"&O26,"") | Y26: =IFERROR(INDEX('Squad Listing'!$A:$A,MATCH(X26,'Squad Listing'!$B:$B,0)),"") | Z26: =IF(T26<>"",B26&"-"&T26&"-"&S26&"-Pos"&U26,"") | AA26: =IF(T26<>"",B26&"-"&T26&"-"&S26,"") | AB26: =IFERROR(INDEX('Squad Listing'!$A:$A,MATCH(AA26,'Squad Listing'!$B:$B,0)),"")
A27: 24-1017 | B27: =INDEX('Tournament List'!$L:$L,MATCH($A27,'Tournament List'!$A:$A,0)) -> Littleton Target Masters | C27: =INDEX('Tournament List'!$B:$B,MATCH($A27,'Tournament List'!$A:$A,0)) -> Jill | D27: =INDEX('Tournament List'!$C:$C,MATCH($A27,'Tournament List'!$A:$A,0)) -> Last Name18 | E27: =IF(C27<>"",C27&" "&D27,"") -> Jill Last Name18 | F27: =INDEX('Tournament List'!$M:$M,MATCH($A27,'Tournament List'!$A:$A,0)) -> Collegiate | G27: Skeet | H27: Collegiate 1 | I27: 2 | K27: =IF(H27<>"",B27&"-"&H27&"-"&G27&"-Pos"&I27,"") -> Littleton Target Masters-Collegiate 1-Skeet-Pos2 | L27: =IF(H27<>"",IFERROR(INDEX('Tournament Setup'!$B$59:$B$78,MATCH(H27,SquadConcurrents,0)),""),"") -> Collegiate | M27: =IFERROR(INDEX('Squad Listing'!$A:$A,MATCH(B27&"-"&H27&"-"&G27,'Squad Listing'!$B:$B,0)),"") -> 172 | N27: =IF(H27<>"",I27,"") -> 2 | O27: Trap | S27: Sporting Clays | W27: =IF(P27<>"",B27&"-"&P27&"-"&O27&"-Pos"&Q27,"") | X27: =IF(P27<>"",B27&"-"&P27&"-"&O27,"") | Y27: =IFERROR(INDEX('Squad Listing'!$A:$A,MATCH(X27,'Squad Listing'!$B:$B,0)),"") | Z27: =IF(T27<>"",B27&"-"&T27&"-"&S27&"-Pos"&U27,"") | AA27: =IF(T27<>"",B27&"-"&T27&"-"&S27,"") | AB27: =IFERROR(INDEX('Squad Listing'!$A:$A,MATCH(AA27,'Squad Listing'!$B:$B,0)),"")
A28: 24-1029 | B28: =INDEX('Tournament List'!$L:$L,MATCH($A28,'Tournament List'!$A:$A,0)) -> Littleton Target Masters | C28: =INDEX('Tournament List'!$B:$B,MATCH($A28,'Tournament List'!$A:$A,0)) -> Judy | D28: =INDEX('Tournament List'!$C:$C,MATCH($A28,'Tournament List'!$A:$A,0)) -> Last Name30 | E28: =IF(C28<>"",C28&" "&D28,"") -> Judy Last Name30 | F28: =INDEX('Tournament List'!$M:$M,MATCH($A28,'Tournament List'!$A:$A,0)) -> Collegiate | G28: Skeet | H28: Collegiate 1 | I28: 3 | K28: =IF(H28<>"",B28&"-"&H28&"-"&G28&"-Pos"&I28,"") -> Littleton Target Masters-Collegiate 1-Skeet-Pos3 | L28: =IF(H28<>"",IFERROR(INDEX('Tournament Setup'!$B$59:$B$78,MATCH(H28,SquadConcurrents,0)),""),"") -> Collegiate | M28: =IFERROR(INDEX('Squad Listing'!$A:$A,MATCH(B28&"-"&H28&"-"&G28,'Squad Listing'!$B:$B,0)),"") -> 172 | N28: =IF(H28<>"",I28,"") -> 3 | O28: Trap | S28: Sporting Clays | W28: =IF(P28<>"",B28&"-"&P28&"-"&O28&"-Pos"&Q28,"") | X28: =IF(P28<>"",B28&"-"&P28&"-"&O28,"") | Y28: =IFERROR(INDEX('Squad Listing'!$A:$A,MATCH(X28,'Squad Listing'!$B:$B,0)),"") | Z28: =IF(T28<>"",B28&"-"&T28&"-"&S28&"-Pos"&U28,"") | AA28: =IF(T28<>"",B28&"-"&T28&"-"&S28,"") | AB28: =IFERROR(INDEX('Squad Listing'!$A:$A,MATCH(AA28,'Squad Listing'!$B:$B,0)),"")
A29: 24-1041 | B29: =INDEX('Tournament List'!$L:$L,MATCH($A29,'Tournament List'!$A:$A,0)) -> Littleton Target Masters | C29: =INDEX('Tournament List'!$B:$B,MATCH($A29,'Tournament List'!$A:$A,0)) -> Owen | D29: =INDEX('Tournament List'!$C:$C,MATCH($A29,'Tournament List'!$A:$A,0)) -> Last Name42 | E29: =IF(C29<>"",C29&" "&D29,"") -> Owen Last Name42 | F29: =INDEX('Tournament List'!$M:$M,MATCH($A29,'Tournament List'!$A:$A,0)) -> Novice | G29: Skeet | H29: Novice 1 | I29: 3 | K29: =IF(H29<>"",B29&"-"&H29&"-"&G29&"-Pos"&I29,"") -> Littleton Target Masters-Novice 1-Skeet-Pos3 | L29: =IF(H29<>"",IFERROR(INDEX('Tournament Setup'!$B$59:$B$78,MATCH(H29,SquadConcurrents,0)),""),"") -> Novice | M29: =IFERROR(INDEX('Squad Listing'!$A:$A,MATCH(B29&"-"&H29&"-"&G29,'Squad Listing'!$B:$B,0)),"") -> 181 | N29: =IF(H29<>"",I29,"") -> 3 | O29: Trap | S29: Sporting Clays | W29: =IF(P29<>"",B29&"-"&P29&"-"&O29&"-Pos"&Q29,"") | X29: =IF(P29<>"",B29&"-"&P29&"-"&O29,"") | Y29: =IFERROR(INDEX('Squad Listing'!$A:$A,MATCH(X29,'Squad Listing'!$B:$B,0)),"") | Z29: =IF(T29<>"",B29&"-"&T29&"-"&S29&"-Pos"&U29,"") | AA29: =IF(T29<>"",B29&"-"&T29&"-"&S29,"") | AB29: =IFERROR(INDEX('Squad Listing'!$A:$A,MATCH(AA29,'Squad Listing'!$B:$B,0)),"")
A30: 24-1005 | B30: =INDEX('Tournament List'!$L:$L,MATCH($A30,'Tournament List'!$A:$A,0)) -> Littleton Target Masters | C30: =INDEX('Tournament List'!$B:$B,MATCH($A30,'Tournament List'!$A:$A,0)) -> Ben | D30: =INDEX('Tournament List'!$C:$C,MATCH($A30,'Tournament List'!$A:$A,0)) -> Last Name6 | E30: =IF(C30<>"",C30&" "&D30,"") -> Ben Last Name6 | F30: =INDEX('Tournament List'!$M:$M,MATCH($A30,'Tournament List'!$A:$A,0)) -> Novice | G30: Skeet | H30: Novice 1 | I30: 2 | K30: =IF(H30<>"",B30&"-"&H30&"-"&G30&"-Pos"&I30,"") -> Littleton Target Masters-Novice 1-Skeet-Pos2 | L30: =IF(H30<>"",IFERROR(INDEX('Tournament Setup'!$B$59:$B$78,MATCH(H30,SquadConcurrents,0)),""),"") -> Novice | M30: =IFERROR(INDEX('Squad Listing'!$A:$A,MATCH(B30&"-"&H30&"-"&G30,'Squad Listing'!$B:$B,0)),"") -> 181 | N30: =IF(H30<>"",I30,"") -> 2 | O30: Trap | S30: Sporting Clays | W30: =IF(P30<>"",B30&"-"&P30&"-"&O30&"-Pos"&Q30,"") | X30: =IF(P30<>"",B30&"-"&P30&"-"&O30,"") | Y30: =IFERROR(INDEX('Squad Listing'!$A:$A,MATCH(X30,'Squad Listing'!$B:$B,0)),"") | Z30: =IF(T30<>"",B30&"-"&T30&"-"&S30&"-Pos"&U30,"") | AA30: =IF(T30<>"",B30&"-"&T30&"-"&S30,"") | AB30: =IFERROR(INDEX('Squad Listing'!$A:$A,MATCH(AA30,'Squad Listing'!$B:$B,0)),"")
A31: 24-1035 | B31: =INDEX('Tournament List'!$L:$L,MATCH($A31,'Tournament List'!$A:$A,0)) -> Littleton Target Masters | C31: =INDEX('Tournament List'!$B:$B,MATCH($A31,'Tournament List'!$A:$A,0)) -> Randy | D31: =INDEX('Tournament List'!$C:$C,MATCH($A31,'Tournament List'!$A:$A,0)) -> Last Name36 | E31: =IF(C31<>"",C31&" "&D31,"") -> Randy Last Name36 | F31: =INDEX('Tournament List'!$M:$M,MATCH($A31,'Tournament List'!$A:$A,0)) -> Novice | G31: Skeet | H31: Novice 1 | I31: 1 | K31: =IF(H31<>"",B31&"-"&H31&"-"&G31&"-Pos"&I31,"") -> Littleton Target Masters-Novice 1-Skeet-Pos1 | L31: =IF(H31<>"",IFERROR(INDEX('Tournament Setup'!$B$59:$B$78,MATCH(H31,SquadConcurrents,0)),""),"") -> Novice | M31: =IFERROR(INDEX('Squad Listing'!$A:$A,MATCH(B31&"-"&H31&"-"&G31,'Squad Listing'!$B:$B,0)),"") -> 181 | N31: =IF(H31<>"",I31,"") -> 1 | O31: Trap | S31: Sporting Clays | W31: =IF(P31<>"",B31&"-"&P31&"-"&O31&"-Pos"&Q31,"") | X31: =IF(P31<>"",B31&"-"&P31&"-"&O31,"") | Y31: =IFERROR(INDEX('Squad Listing'!$A:$A,MATCH(X31,'Squad Listing'!$B:$B,0)),"") | Z31: =IF(T31<>"",B31&"-"&T31&"-"&S31&"-Pos"&U31,"") | AA31: =IF(T31<>"",B31&"-"&T31&"-"&S31,"") | AB31: =IFERROR(INDEX('Squad Listing'!$A:$A,MATCH(AA31,'Squad Listing'!$B:$B,0)),"")
A32: 24-1047 | B32: =INDEX('Tournament List'!$L:$L,MATCH($A32,'Tournament List'!$A:$A,0)) -> Littleton Target Masters | C32: =INDEX('Tournament List'!$B:$B,MATCH($A32,'Tournament List'!$A:$A,0)) -> Jackson | D32: =INDEX('Tournament List'!$C:$C,MATCH($A32,'Tournament List'!$A:$A,0)) -> Last Name48 | E32: =IF(C32<>"",C32&" "&D32,"") -> Jackson Last Name48 | F32: =INDEX('Tournament List'!$M:$M,MATCH($A32,'Tournament List'!$A:$A,0)) -> Novice | G32: Skeet | K32: =IF(H32<>"",B32&"-"&H32&"-"&G32&"-Pos"&I32,"") | L32: =IF(H32<>"",IFERROR(INDEX('Tournament Setup'!$B$59:$B$78,MATCH(H32,SquadConcurrents,0)),""),"") | M32: =IFERROR(INDEX('Squad Listing'!$A:$A,MATCH(B32&"-"&H32&"-"&G32,'Squad Listing'!$B:$B,0)),"") | N32: =IF(H32<>"",I32,"") | O32: Trap | S32: Sporting Clays | W32: =IF(P32<>"",B32&"-"&P32&"-"&O32&"-Pos"&Q32,"") | X32: =IF(P32<>"",B32&"-"&P32&"-"&O32,"") | Y32: =IFERROR(INDEX('Squad Listing'!$A:$A,MATCH(X32,'Squad Listing'!$B:$B,0)),"") | Z32: =IF(T32<>"",B32&"-"&T32&"-"&S32&"-Pos"&U32,"") | AA32: =IF(T32<>"",B32&"-"&T32&"-"&S32,"") | AB32: =IFERROR(INDEX('Squad Listing'!$A:$A,MATCH(AA32,'Squad Listing'!$B:$B,0)),"")
A33: 24-1023 | B33: =INDEX('Tournament List'!$L:$L,MATCH($A33,'Tournament List'!$A:$A,0)) -> Littleton Target Masters | C33: =INDEX('Tournament List'!$B:$B,MATCH($A33,'Tournament List'!$A:$A,0)) -> Tim | D33: =INDEX('Tournament List'!$C:$C,MATCH($A33,'Tournament List'!$A:$A,0)) -> Last Name24 | E33: =IF(C33<>"",C33&" "&D33,"") -> Tim Last Name24 | F33: =INDEX('Tournament List'!$M:$M,MATCH($A33,'Tournament List'!$A:$A,0)) -> Novice | G33: Skeet | K33: =IF(H33<>"",B33&"-"&H33&"-"&G33&"-Pos"&I33,"") | L33: =IF(H33<>"",IFERROR(INDEX('Tournament Setup'!$B$59:$B$78,MATCH(H33,SquadConcurrents,0)),""),"") | M33: =IFERROR(INDEX('Squad Listing'!$A:$A,MATCH(B33&"-"&H33&"-"&G33,'Squad Listing'!$B:$B,0)),"") | N33: =IF(H33<>"",I33,"") | O33: Trap | S33: Sporting Clays | W33: =IF(P33<>"",B33&"-"&P33&"-"&O33&"-Pos"&Q33,"") | X33: =IF(P33<>"",B33&"-"&P33&"-"&O33,"") | Y33: =IFERROR(INDEX('Squad Listing'!$A:$A,MATCH(X33,'Squad Listing'!$B:$B,0)),"") | Z33: =IF(T33<>"",B33&"-"&T33&"-"&S33&"-Pos"&U33,"") | AA33: =IF(T33<>"",B33&"-"&T33&"-"&S33,"") | AB33: =IFERROR(INDEX('Squad Listing'!$A:$A,MATCH(AA33,'Squad Listing'!$B:$B,0)),"")
A34: 24-1019 | B34: =INDEX('Tournament List'!$L:$L,MATCH($A34,'Tournament List'!$A:$A,0)) -> Rocky Mountain Clay Busters | C34: =INDEX('Tournament List'!$B:$B,MATCH($A34,'Tournament List'!$A:$A,0)) -> Chris | D34: =INDEX('Tournament List'!$C:$C,MATCH($A34,'Tournament List'!$A:$A,0)) -> Last Name20 | E34: =IF(C34<>"",C34&" "&D34,"") -> Chris Last Name20 | F34: =INDEX('Tournament List'!$M:$M,MATCH($A34,'Tournament List'!$A:$A,0)) -> Junior Varsity | G34: Skeet | K34: =IF(H34<>"",B34&"-"&H34&"-"&G34&"-Pos"&I34,"") | L34: =IF(H34<>"",IFERROR(INDEX('Tournament Setup'!$B$59:$B$78,MATCH(H34,SquadConcurrents,0)),""),"") | M34: =IFERROR(INDEX('Squad Listing'!$A:$A,MATCH(B34&"-"&H34&"-"&G34,'Squad Listing'!$B:$B,0)),"") | N34: =IF(H34<>"",I34,"") | O34: Trap | S34: Sporting Clays | W34: =IF(P34<>"",B34&"-"&P34&"-"&O34&"-Pos"&Q34,"") | X34: =IF(P34<>"",B34&"-"&P34&"-"&O34,"") | Y34: =IFERROR(INDEX('Squad Listing'!$A:$A,MATCH(X34,'Squad Listing'!$B:$B,0)),"") | Z34: =IF(T34<>"",B34&"-"&T34&"-"&S34&"-Pos"&U34,"") | AA34: =IF(T34<>"",B34&"-"&T34&"-"&S34,"") | AB34: =IFERROR(INDEX('Squad Listing'!$A:$A,MATCH(AA34,'Squad Listing'!$B:$B,0)),"")
A35: 24-1001 | B35: =INDEX('Tournament List'!$L:$L,MATCH($A35,'Tournament List'!$A:$A,0)) -> Rocky Mountain Clay Busters | C35: =INDEX('Tournament List'!$B:$B,MATCH($A35,'Tournament List'!$A:$A,0)) -> John | D35: =INDEX('Tournament List'!$C:$C,MATCH($A35,'Tournament List'!$A:$A,0)) -> Last Name2 | E35: =IF(C35<>"",C35&" "&D35,"") -> John Last Name2 | F35: =INDEX('Tournament List'!$M:$M,MATCH($A35,'Tournament List'!$A:$A,0)) -> Junior Varsity | G35: Skeet | K35: =IF(H35<>"",B35&"-"&H35&"-"&G35&"-Pos"&I35,"") | L35: =IF(H35<>"",IFERROR(INDEX('Tournament Setup'!$B$59:$B$78,MATCH(H35,SquadConcurrents,0)),""),"") | M35: =IFERROR(INDEX('Squad Listing'!$A:$A,MATCH(B35&"-"&H35&"-"&G35,'Squad Listing'!$B:$B,0)),"") | N35: =IF(H35<>"",I35,"") | O35: Trap | S35: Sporting Clays | W35: =IF(P35<>"",B35&"-"&P35&"-"&O35&"-Pos"&Q35,"") | X35: =IF(P35<>"",B35&"-"&P35&"-"&O35,"") | Y35: =IFERROR(INDEX('Squad Listing'!$A:$A,MATCH(X35,'Squad Listing'!$B:$B,0)),"") | Z35: =IF(T35<>"",B35&"-"&T35&"-"&S35&"-Pos"&U35,"") | AA35: =IF(T35<>"",B35&"-"&T35&"-"&S35,"") | AB35: =IFERROR(INDEX('Squad Listing'!$A:$A,MATCH(AA35,'Squad Listing'!$B:$B,0)),"")
A36: 24-1007 | B36: =INDEX('Tournament List'!$L:$L,MATCH($A36,'Tournament List'!$A:$A,0)) -> Rocky Mountain Clay Busters | C36: =INDEX('Tournament List'!$B:$B,MATCH($A36,'Tournament List'!$A:$A,0)) -> James | D36: =INDEX('Tournament List'!$C:$C,MATCH($A36,'Tournament List'!$A:$A,0)) -> Last Name8 | E36: =IF(C36<>"",C36&" "&D36,"") -> James Last Name8 | F36: =INDEX('Tournament List'!$M:$M,MATCH($A36,'Tournament List'!$A:$A,0)) -> Junior Varsity | G36: Skeet | H36: Junior Varsity 1 | I36: 2 | K36: =IF(H36<>"",B36&"-"&H36&"-"&G36&"-Pos"&I36,"") -> Rocky Mountain Clay Busters-Junior Varsity 1-Skeet-Pos2 | L36: =IF(H36<>"",IFERROR(INDEX('Tournament Setup'!$B$59:$B$78,MATCH(H36,SquadConcurrents,0)),""),"") -> Junior Varsity | M36: =IFERROR(INDEX('Squad Listing'!$A:$A,MATCH(B36&"-"&H36&"-"&G36,'Squad Listing'!$B:$B,0)),"") -> 235 | N36: =IF(H36<>"",I36,"") -> 2 | O36: Trap | S36: Sporting Clays | W36: =IF(P36<>"",B36&"-"&P36&"-"&O36&"-Pos"&Q36,"") | X36: =IF(P36<>"",B36&"-"&P36&"-"&O36,"") | Y36: =IFERROR(INDEX('Squad Listing'!$A:$A,MATCH(X36,'Squad Listing'!$B:$B,0)),"") | Z36: =IF(T36<>"",B36&"-"&T36&"-"&S36&"-Pos"&U36,"") | AA36: =IF(T36<>"",B36&"-"&T36&"-"&S36,"") | AB36: =IFERROR(INDEX('Squad Listing'!$A:$A,MATCH(AA36,'Squad Listing'!$B:$B,0)),"")
A37: 24-1025 | B37: =INDEX('Tournament List'!$L:$L,MATCH($A37,'Tournament List'!$A:$A,0)) -> Rocky Mountain Clay Busters | C37: =INDEX('Tournament List'!$B:$B,MATCH($A37,'Tournament List'!$A:$A,0)) -> Gary | D37: =INDEX('Tournament List'!$C:$C,MATCH($A37,'Tournament List'!$A:$A,0)) -> Last Name26 | E37: =IF(C37<>"",C37&" "&D37,"") -> Gary Last Name26 | F37: =INDEX('Tournament List'!$M:$M,MATCH($A37,'Tournament List'!$A:$A,0)) -> Junior Varsity | G37: Skeet | H37: Junior Varsity 1 | I37: 1 | K37: =IF(H37<>"",B37&"-"&H37&"-"&G37&"-Pos"&I37,"") -> Rocky Mountain Clay Busters-Junior Varsity 1-Skeet-Pos1 | L37: =IF(H37<>"",IFERROR(INDEX('Tournament Setup'!$B$59:$B$78,MATCH(H37,SquadConcurrents,0)),""),"") -> Junior Varsity | M37: =IFERROR(INDEX('Squad Listing'!$A:$A,MATCH(B37&"-"&H37&"-"&G37,'Squad Listing'!$B:$B,0)),"") -> 235 | N37: =IF(H37<>"",I37,"") -> 1 | O37: Trap | S37: Sporting Clays | W37: =IF(P37<>"",B37&"-"&P37&"-"&O37&"-Pos"&Q37,"") | X37: =IF(P37<>"",B37&"-"&P37&"-"&O37,"") | Y37: =IFERROR(INDEX('Squad Listing'!$A:$A,MATCH(X37,'Squad Listing'!$B:$B,0)),"") | Z37: =IF(T37<>"",B37&"-"&T37&"-"&S37&"-Pos"&U37,"") | AA37: =IF(T37<>"",B37&"-"&T37&"-"&S37,"") | AB37: =IFERROR(INDEX('Squad Listing'!$A:$A,MATCH(AA37,'Squad Listing'!$B:$B,0)),"")
A38: 24-1037 | B38: =INDEX('Tournament List'!$L:$L,MATCH($A38,'Tournament List'!$A:$A,0)) -> Rocky Mountain Clay Busters | C38: =INDEX('Tournament List'!$B:$B,MATCH($A38,'Tournament List'!$A:$A,0)) -> Stuart | D38: =INDEX('Tournament List'!$C:$C,MATCH($A38,'Tournament List'!$A:$A,0)) -> Last Name38 | E38: =IF(C38<>"",C38&" "&D38,"") -> Stuart Last Name38 | F38: =INDEX('Tournament List'!$M:$M,MATCH($A38,'Tournament List'!$A:$A,0)) -> Junior Varsity | G38: Skeet | H38: Junior Varsity 1 | I38: 3 | K38: =IF(H38<>"",B38&"-"&H38&"-"&G38&"-Pos"&I38,"") -> Rocky Mountain Clay Busters-Junior Varsity 1-Skeet-Pos3 | L38: =IF(H38<>"",IFERROR(INDEX('Tournament Setup'!$B$59:$B$78,MATCH(H38,SquadConcurrents,0)),""),"") -> Junior Varsity | M38: =IFERROR(INDEX('Squad Listing'!$A:$A,MATCH(B38&"-"&H38&"-"&G38,'Squad Listing'!$B:$B,0)),"") -> 235 | N38: =IF(H38<>"",I38,"") -> 3 | O38: Trap | S38: Sporting Clays | W38: =IF(P38<>"",B38&"-"&P38&"-"&O38&"-Pos"&Q38,"") | X38: =IF(P38<>"",B38&"-"&P38&"-"&O38,"") | Y38: =IFERROR(INDEX('Squad Listing'!$A:$A,MATCH(X38,'Squad Listing'!$B:$B,0)),"") | Z38: =IF(T38<>"",B38&"-"&T38&"-"&S38&"-Pos"&U38,"") | AA38: =IF(T38<>"",B38&"-"&T38&"-"&S38,"") | AB38: =IFERROR(INDEX('Squad Listing'!$A:$A,MATCH(AA38,'Squad Listing'!$B:$B,0)),"")
A39: 24-1031 | B39: =INDEX('Tournament List'!$L:$L,MATCH($A39,'Tournament List'!$A:$A,0)) -> Rocky Mountain Clay Busters | C39: =INDEX('Tournament List'!$B:$B,MATCH($A39,'Tournament List'!$A:$A,0)) -> Kelly | D39: =INDEX('Tournament List'!$C:$C,MATCH($A39,'Tournament List'!$A:$A,0)) -> Last Name32 | E39: =IF(C39<>"",C39&" "&D39,"") -> Kelly Last Name32 | F39: =INDEX('Tournament List'!$M:$M,MATCH($A39,'Tournament List'!$A:$A,0)) -> Intermediate | G39: Skeet | H39: Intermediate 1 | I39: 3 | K39: =IF(H39<>"",B39&"-"&H39&"-"&G39&"-Pos"&I39,"") -> Rocky Mountain Clay Busters-Intermediate 1-Skeet-Pos3 | L39: =IF(H39<>"",IFERROR(INDEX('Tournament Setup'!$B$59:$B$78,MATCH(H39,SquadConcurrents,0)),""),"") -> Intermediate | M39: =IFERROR(INDEX('Squad Listing'!$A:$A,MATCH(B39&"-"&H39&"-"&G39,'Squad Listing'!$B:$B,0)),"") -> 232 | N39: =IF(H39<>"",I39,"") -> 3 | O39: Trap | S39: Sporting Clays | W39: =IF(P39<>"",B39&"-"&P39&"-"&O39&"-Pos"&Q39,"") | X39: =IF(P39<>"",B39&"-"&P39&"-"&O39,"") | Y39: =IFERROR(INDEX('Squad Listing'!$A:$A,MATCH(X39,'Squad Listing'!$B:$B,0)),"") | Z39: =IF(T39<>"",B39&"-"&T39&"-"&S39&"-Pos"&U39,"") | AA39: =IF(T39<>"",B39&"-"&T39&"-"&S39,"") | AB39: =IFERROR(INDEX('Squad Listing'!$A:$A,MATCH(AA39,'Squad Listing'!$B:$B,0)),"")
A40: 24-1043 | B40: =INDEX('Tournament List'!$L:$L,MATCH($A40,'Tournament List'!$A:$A,0)) -> Rocky Mountain Clay Busters | C40: =INDEX('Tournament List'!$B:$B,MATCH($A40,'Tournament List'!$A:$A,0)) -> Trisha | D40: =INDEX('Tournament List'!$C:$C,MATCH($A40,'Tournament List'!$A:$A,0)) -> Last Name44 | E40: =IF(C40<>"",C40&" "&D40,"") -> Trisha Last Name44 | F40: =INDEX('Tournament List'!$M:$M,MATCH($A40,'Tournament List'!$A:$A,0)) -> Intermediate | G40: Skeet | H40: Intermediate 1 | I40: 1 | K40: =IF(H40<>"",B40&"-"&H40&"-"&G40&"-Pos"&I40,"") -> Rocky Mountain Clay Busters-Intermediate 1-Skeet-Pos1 | L40: =IF(H40<>"",IFERROR(INDEX('Tournament Setup'!$B$59:$B$78,MATCH(H40,SquadConcurrents,0)),""),"") -> Intermediate | M40: =IFERROR(INDEX('Squad Listing'!$A:$A,MATCH(B40&"-"&H40&"-"&G40,'Squad Listing'!$B:$B,0)),"") -> 232 | N40: =IF(H40<>"",I40,"") -> 1 | O40: Trap | S40: Sporting Clays | W40: =IF(P40<>"",B40&"-"&P40&"-"&O40&"-Pos"&Q40,"") | X40: =IF(P40<>"",B40&"-"&P40&"-"&O40,"") | Y40: =IFERROR(INDEX('Squad Listing'!$A:$A,MATCH(X40,'Squad Listing'!$B:$B,0)),"") | Z40: =IF(T40<>"",B40&"-"&T40&"-"&S40&"-Pos"&U40,"") | AA40: =IF(T40<>"",B40&"-"&T40&"-"&S40,"") | AB40: =IFERROR(INDEX('Squad Listing'!$A:$A,MATCH(AA40,'Squad Listing'!$B:$B,0)),"")
...

Sheet Squad Listing
A1: Squad # | B1: Squad Key | C1: Team Name | D1: Team Concurrent | E1: Concurrent Squad | F1: Discipline | G1: Participant #1 ID | H1: Participant #1 Name | I1: Participant #2 ID | J1: Participant #2 Name | K1: Participant #3 ID | L1: Participant #3 Name | M1: Participant #4 ID | N1: Participant #4 Name | O1: Participant #5 ID | P1: Participant #5 Name
A2: 1 | B2: =C2&"-"&E2&"-"&F2 -> Brighton Clay Crushers-Collegiate 1-Skeet | C2: Brighton Clay Crushers | D2: =INDEX('Tournament Setup'!$B$59:$B$78,MATCH(E2,SquadConcurrents,0)) -> Collegiate | E2: Collegiate 1 | F2: Skeet | G2: =IF(F2="Skeet",IFERROR(INDEX('Shooter-Squad Assignment'!$A:$A,MATCH(C2&"-"&E2&"-"&F2&"-Pos1",'Shooter-Squad Assignment'!$K:$K,0)),""),IF(F2="Trap",IFERROR(INDEX('Shooter-Squad Assignment'!$A:$A,MATCH(C2&"-"&E2&"-"&F2&"-Pos1",'Shooter-Squad Assignment'!$W:$W,0)),""),IF(F2="Sporting Clays",IFERROR(INDEX('Shooter-Squad Assignment'!$A:$A,MATCH(C2&"-"&E2&"-"&F2&"-Pos1",'Shooter-Squad Assignment'!$Z:$Z,0)),""),""))) | H2: =IF(ISBLANK(G2),"",IFERROR(INDEX('Tournament List'!$D:$D,MATCH(G2,'Tournament List'!$A:$A,0)),"")) | I2: =IF(F2="Skeet",IFERROR(INDEX('Shooter-Squad Assignment'!$A:$A,MATCH(C2&"-"&E2&"-"&F2&"-Pos2",'Shooter-Squad Assignment'!$K:$K,0)),""),IF(F2="Trap",IFERROR(INDEX('Shooter-Squad Assignment'!$A:$A,MATCH(C2&"-"&E2&"-"&F2&"-Pos2",'Shooter-Squad Assignment'!$W:$W,0)),""),IF(F2="Sporting Clays",IFERROR(INDEX('Shooter-Squad Assignment'!$A:$A,MATCH(C2&"-"&E2&"-"&F2&"-Pos2",'Shooter-Squad Assignment'!$Z:$Z,0)),""),""))) | J2: =IF(ISBLANK(I2),"",IFERROR(INDEX('Tournament List'!$D:$D,MATCH(I2,'Tournament List'!$A:$A,0)),"")) | K2: =IF(F2="Skeet",IFERROR(INDEX('Shooter-Squad Assignment'!$A:$A,MATCH(C2&"-"&E2&"-"&F2&"-Pos3",'Shooter-Squad Assignment'!$K:$K,0)),""),IF(F2="Trap",IFERROR(INDEX('Shooter-Squad Assignment'!$A:$A,MATCH(C2&"-"&E2&"-"&F2&"-Pos3",'Shooter-Squad Assignment'!$W:$W,0)),""),IF(F2="Sporting Clays",IFERROR(INDEX('Shooter-Squad Assignment'!$A:$A,MATCH(C2&"-"&E2&"-"&F2&"-Pos3",'Shooter-Squad Assignment'!$Z:$Z,0)),""),""))) | L2: =IF(ISBLANK(K2),"",IFERROR(INDEX('Tournament List'!$D:$D,MATCH(K2,'Tournament List'!$A:$A,0)),"")) | M2: =IF(F2="Skeet",IFERROR(INDEX('Shooter-Squad Assignment'!$A:$A,MATCH(C2&"-"&E2&"-"&F2&"-Pos4",'Shooter-Squad Assignment'!$K:$K,0)),""),IF(F2="Trap",IFERROR(INDEX('Shooter-Squad Assignment'!$A:$A,MATCH(C2&"-"&E2&"-"&F2&"-Pos4",'Shooter-Squad Assignment'!$W:$W,0)),""),IF(F2="Sporting Clays",IFERROR(INDEX('Shooter-Squad Assignment'!$A:$A,MATCH(C2&"-"&E2&"-"&F2&"-Pos4",'Shooter-Squad Assignment'!$Z:$Z,0)),""),""))) | N2: =IF(ISBLANK(M2),"",IFERROR(INDEX('Tournament List'!$D:$D,MATCH(M2,'Tournament List'!$A:$A,0)),"")) | O2: =IF(F2="Skeet",IFERROR(INDEX('Shooter-Squad Assignment'!$A:$A,MATCH(C2&"-"&E2&"-"&F2&"-Pos5",'Shooter-Squad Assignment'!$K:$K,0)),""),IF(F2="Trap",IFERROR(INDEX('Shooter-Squad Assignment'!$A:$A,MATCH(C2&"-"&E2&"-"&F2&"-Pos5",'Shooter-Squad Assignment'!$W:$W,0)),""),IF(F2="Sporting Clays",IFERROR(INDEX('Shooter-Squad Assignment'!$A:$A,MATCH(C2&"-"&E2&"-"&F2&"-Pos5",'Shooter-Squad Assignment'!$Z:$Z,0)),""),""))) | P2: =IF(ISBLANK(O2),"",IFERROR(INDEX('Tournament List'!$D:$D,MATCH(O2,'Tournament List'!$A:$A,0)),""))
